Workbook

Sheet Start Here
B2: The Year-on-Year Sales Workbook
B3: A blank template from adamreflects.ie — nothing of my shop travels with it.
B5: What this is
B6: This is the workbook I keep for my own jewellers, emptied out. It tracks every half hour the shop is open:
B7: how many people walked in, how many bought, and what they spent. Everything else in here is worked out from
B8: those three numbers.
B10: The point of it is comparison. A day's takings on its own tells you almost nothing. The same day against last
B11: week, and against the same day last year, tells you a lot.
B13: Do these three things first
B14: 1. Open the Setup tab and fill in the yellow cells. Start date, your markup, your rent. Two minutes.
B15: 2. Open the Last Year tab and paste in last year's daily takings, if you have them. If you don't, skip it —
B16: everything still works, you just won't get the year-on-year columns until this time next year.
... B57: adamreflects.ie · free to use, free to change · built between customers, in a jewellers in Cork

Sheet Setup
B2: Setup — fill in the yellow cells
B3: Everything in the workbook reads from here. Change a number and the whole thing follows.
B4: YOUR NUMBERS
B5: Week 1 start date | C5: 46027 | D5: The first day of your week 1. Every date in the workbook counts on from this.
B6: Markup divisor | C6: 5.2 | D6: Sale price divided by this = rough cost. If you sell at 3x cost, put 3. Mine is 5.2.
B7: Rent per week (€) | C7: 0 | D7: Leave 0 if you'd rather not track it.
B8: Rates / service charge per week (€) | C8: 0 | D8: Same again — 0 is fine.
B9: Packaging & consumables (% of sales) | C9: 0.03 | D9: Bags, boxes, till roll. 3% is a reasonable guess if you don't know.
B10: Tax rate (%) | C10: 0.3 | D10: Only used for the 'after tax' line. A rough steer, not a tax return.
B11: Last year's week 1 start date | C11: =C5-364 -> 45663 | D11: Defaults to 364 days before your start date, so days of the week line up.
B13: OPENING HOURS
B14: The week tabs run 9.00am to 7.00pm in half hours. If you open later or close earlier, just leave those
B15: rows blank — empty rows add up to nothing and cost you nothing. Don't delete them; the sums use them.
B17: THE TRACKED CATEGORY
B18: One column on every week tab is for a category you want to watch on its own. I use gold, because it
B19: behaves completely differently to silver. Yours might be repairs, or a brand, or anything at all.

Sheet Wk1
A1: Day | B1: Date | C1: Time | D1: Customers In | E1: Sales | F1: Vouchers Used | G1: Walk In/Out | H1: Sale Amount | I1: Conversion | J1: Avg Sale | K1: Tracked Category | L1: Notes | M1: Cash | N1: vs Last Wk € | O1: vs Last Wk Cust | P1: Est. Cost | Q1: Est. Profit | R1: Last Year Day | S1: vs Last Year
A2: =TEXT(Setup!$C$5+0,"dddd") -> Monday | B2: =Setup!$C$5+0 -> 46027 | C2: 9.00 - 9.30 | P2: =IFERROR(H2/Setup!$C$6,"") -> 0 | Q2: =IFERROR(H2-P2,"") -> 0
A3: =TEXT(Setup!$C$5+0,"dddd") -> Monday | B3: =Setup!$C$5+0 -> 46027 | C3: 9.30 - 10.00 | P3: =IFERROR(H3/Setup!$C$6,"") -> 0 | Q3: =IFERROR(H3-P3,"") -> 0
A4: =TEXT(Setup!$C$5+0,"dddd") -> Monday | B4: =Setup!$C$5+0 -> 46027 | C4: 10.00 - 10.30 | P4: =IFERROR(H4/Setup!$C$6,"") -> 0 | Q4: =IFERROR(H4-P4,"") -> 0
A5: =TEXT(Setup!$C$5+0,"dddd") -> Monday | B5: =Setup!$C$5+0 -> 46027 | C5: 10.30 - 11.00 | P5: =IFERROR(H5/Setup!$C$6,"") -> 0 | Q5: =IFERROR(H5-P5,"") -> 0
A6: =TEXT(Setup!$C$5+0,"dddd") -> Monday | B6: =Setup!$C$5+0 -> 46027 | C6: 11.00 - 11.30 | P6: =IFERROR(H6/Setup!$C$6,"") -> 0 | Q6: =IFERROR(H6-P6,"") -> 0
A7: =TEXT(Setup!$C$5+0,"dddd") -> Monday | B7: =Setup!$C$5+0 -> 46027 | C7: 11.30 - 12.00 | P7: =IFERROR(H7/Setup!$C$6,"") -> 0 | Q7: =IFERROR(H7-P7,"") -> 0
A8: =TEXT(Setup!$C$5+0,"dddd") -> Monday | B8: =Setup!$C$5+0 -> 46027 | C8: 12.00 - 12.30 | P8: =IFERROR(H8/Setup!$C$6,"") -> 0 | Q8: =IFERROR(H8-P8,"") -> 0
A9: =TEXT(Setup!$C$5+0,"dddd") -> Monday | B9: =Setup!$C$5+0 -> 46027 | C9: 12.30 - 13.00 | P9: =IFERROR(H9/Setup!$C$6,"") -> 0 | Q9: =IFERROR(H9-P9,"") -> 0
A10: =TEXT(Setup!$C$5+0,"dddd") -> Monday | B10: =Setup!$C$5+0 -> 46027 | C10: 13.00 - 13.30 | P10: =IFERROR(H10/Setup!$C$6,"") -> 0 | Q10: =IFERROR(H10-P10,"") -> 0
A11: =TEXT(Setup!$C$5+0,"dddd") -> Monday | B11: =Setup!$C$5+0 -> 46027 | C11: 13.30 - 14.00 | P11: =IFERROR(H11/Setup!$C$6,"") -> 0 | Q11: =IFERROR(H11-P11,"") -> 0
A12: =TEXT(Setup!$C$5+0,"dddd") -> Monday | B12: =Setup!$C$5+0 -> 46027 | C12: 14.00 - 14.30 | P12: =IFERROR(H12/Setup!$C$6,"") -> 0 | Q12: =IFERROR(H12-P12,"") -> 0
A13: =TEXT(Setup!$C$5+0,"dddd") -> Monday | B13: =Setup!$C$5+0 -> 46027 | C13: 14.30 - 15.00 | P13: =IFERROR(H13/Setup!$C$6,"") -> 0 | Q13: =IFERROR(H13-P13,"") -> 0
... A22: =TEXT(Setup!$C$5+0,"dddd") -> Monday | B22: =Setup!$C$5+0 -> 46027 | C22: ONLINE | P22: =IFERROR(H22/Setup!$C$6,"") -> 0 | Q22: =IFERROR(H22-P22,"") -> 0
A23: =TEXT(Setup!$C$5+0,"dddd") -> Monday | B23: =Setup!$C$5+0 -> 46027 | C23: TOTAL | D23: =SUM(D2:D22) -> 0 | E23: =SUM(E2:E22) -> 0 | F23: =SUM(F2:F22) -> 0 | G23: =SUM(G2:G22) -> 0 | H23: =SUM(H2:H22) -> 0 | I23: =IFERROR(E23/D23,"") | J23: =IFERROR(H23/E23,"") | K23: =SUM(K2:K22) -> 0 | M23: =SUM(M2:M22) -> 0 | P23: =SUM(P2:P22) -> 0 | Q23: =SUM(Q2:Q22) -> 0 | R23: =IFERROR(INDEX('Last Year'!$C$6:$C$369,MATCH(B23-364,'Last Year'!$B$6:$B$369,0)),"") -> 0 | S23: =IFERROR(H23/R23-1,"")
A24: =TEXT(Setup!$C$5+1,"dddd") -> Tuesday | B24: =Setup!$C$5+1 -> 46028 | C24: 9.00 - 9.30 | P24: =IFERROR(H24/Setup!$C$6,"") -> 0 | Q24: =IFERROR(H24-P24,"") -> 0
A25: =TEXT(Setup!$C$5+1,"dddd") -> Tuesday | B25: =Setup!$C$5+1 -> 46028 | C25: 9.30 - 10.00 | P25: =IFERROR(H25/Setup!$C$6,"") -> 0 | Q25: =IFERROR(H25-P25,"") -> 0
A26: =TEXT(Setup!$C$5+1,"dddd") -> Tuesday | B26: =Setup!$C$5+1 -> 46028 | C26: 10.00 - 10.30 | P26: =IFERROR(H26/Setup!$C$6,"") -> 0 | Q26: =IFERROR(H26-P26,"") -> 0
A27: =TEXT(Setup!$C$5+1,"dddd") -> Tuesday | B27: =Setup!$C$5+1 -> 46028 | C27: 10.30 - 11.00 | P27: =IFERROR(H27/Setup!$C$6,"") -> 0 | Q27: =IFERROR(H27-P27,"") -> 0
A28: =TEXT(Setup!$C$5+1,"dddd") -> Tuesday | B28: =Setup!$C$5+1 -> 46028 | C28: 11.00 - 11.30 | P28: =IFERROR(H28/Setup!$C$6,"") -> 0 | Q28: =IFERROR(H28-P28,"") -> 0
A29: =TEXT(Setup!$C$5+1,"dddd") -> Tuesday | B29: =Setup!$C$5+1 -> 46028 | C29: 11.30 - 12.00 | P29: =IFERROR(H29/Setup!$C$6,"") -> 0 | Q29: =IFERROR(H29-P29,"") -> 0
A30: =TEXT(Setup!$C$5+1,"dddd") -> Tuesday | B30: =Setup!$C$5+1 -> 46028 | C30: 12.00 - 12.30 | P30: =IFERROR(H30/Setup!$C$6,"") -> 0 | Q30: =IFERROR(H30-P30,"") -> 0
A31: =TEXT(Setup!$C$5+1,"dddd") -> Tuesday | B31: =Setup!$C$5+1 -> 46028 | C31: 12.30 - 13.00 | P31: =IFERROR(H31/Setup!$C$6,"") -> 0 | Q31: =IFERROR(H31-P31,"") -> 0
A32: =TEXT(Setup!$C$5+1,"dddd") -> Tuesday | B32: =Setup!$C$5+1 -> 46028 | C32: 13.00 - 13.30 | P32: =IFERROR(H32/Setup!$C$6,"") -> 0 | Q32: =IFERROR(H32-P32,"") -> 0
A33: =TEXT(Setup!$C$5+1,"dddd") -> Tuesday | B33: =Setup!$C$5+1 -> 46028 | C33: 13.30 - 14.00 | P33: =IFERROR(H33/Setup!$C$6,"") -> 0 | Q33: =IFERROR(H33-P33,"") -> 0
A34: =TEXT(Setup!$C$5+1,"dddd") -> Tuesday | B34: =Setup!$C$5+1 -> 46028 | C34: 14.00 - 14.30 | P34: =IFERROR(H34/Setup!$C$6,"") -> 0 | Q34: =IFERROR(H34-P34,"") -> 0
A35: =TEXT(Setup!$C$5+1,"dddd") -> Tuesday | B35: =Setup!$C$5+1 -> 46028 | C35: 14.30 - 15.00 | P35: =IFERROR(H35/Setup!$C$6,"") -> 0 | Q35: =IFERROR(H35-P35,"") -> 0
... A44: =TEXT(Setup!$C$5+1,"dddd") -> Tuesday | B44: =Setup!$C$5+1 -> 46028 | C44: ONLINE | P44: =IFERROR(H44/Setup!$C$6,"") -> 0 | Q44: =IFERROR(H44-P44,"") -> 0
A45: =TEXT(Setup!$C$5+1,"dddd") -> Tuesday | B45: =Setup!$C$5+1 -> 46028 | C45: TOTAL | D45: =SUM(D24:D44) -> 0 | E45: =SUM(E24:E44) -> 0 | F45: =SUM(F24:F44) -> 0 | G45: =SUM(G24:G44) -> 0 | H45: =SUM(H24:H44) -> 0 | I45: =IFERROR(E45/D45,"") | J45: =IFERROR(H45/E45,"") | K45: =SUM(K24:K44) -> 0 | M45: =SUM(M24:M44) -> 0 | P45: =SUM(P24:P44) -> 0 | Q45: =SUM(Q24:Q44) -> 0 | R45: =IFERROR(INDEX('Last Year'!$C$6:$C$369,MATCH(B45-364,'Last Year'!$B$6:$B$369,0)),"") -> 0 | S45: =IFERROR(H45/R45-1,"")
A46: =TEXT(Setup!$C$5+2,"dddd") -> Wednesday | B46: =Setup!$C$5+2 -> 46029 | C46: 9.00 - 9.30 | P46: =IFERROR(H46/Setup!$C$6,"") -> 0 | Q46: =IFERROR(H46-P46,"") -> 0
A47: =TEXT(Setup!$C$5+2,"dddd") -> Wednesday | B47: =Setup!$C$5+2 -> 46029 | C47: 9.30 - 10.00 | P47: =IFERROR(H47/Setup!$C$6,"") -> 0 | Q47: =IFERROR(H47-P47,"") -> 0
A48: =TEXT(Setup!$C$5+2,"dddd") -> Wednesday | B48: =Setup!$C$5+2 -> 46029 | C48: 10.00 - 10.30 | P48: =IFERROR(H48/Setup!$C$6,"") -> 0 | Q48: =IFERROR(H48-P48,"") -> 0
A49: =TEXT(Setup!$C$5+2,"dddd") -> Wednesday | B49: =Setup!$C$5+2 -> 46029 | C49: 10.30 - 11.00 | P49: =IFERROR(H49/Setup!$C$6,"") -> 0 | Q49: =IFERROR(H49-P49,"") -> 0
A50: =TEXT(Setup!$C$5+2,"dddd") -> Wednesday | B50: =Setup!$C$5+2 -> 46029 | C50: 11.00 - 11.30 | P50: =IFERROR(H50/Setup!$C$6,"") -> 0 | Q50: =IFERROR(H50-P50,"") -> 0
A51: =TEXT(Setup!$C$5+2,"dddd") -> Wednesday | B51: =Setup!$C$5+2 -> 46029 | C51: 11.30 - 12.00 | P51: =IFERROR(H51/Setup!$C$6,"") -> 0 | Q51: =IFERROR(H51-P51,"") -> 0
A52: =TEXT(Setup!$C$5+2,"dddd") -> Wednesday | B52: =Setup!$C$5+2 -> 46029 | C52: 12.00 - 12.30 | P52: =IFERROR(H52/Setup!$C$6,"") -> 0 | Q52: =IFERROR(H52-P52,"") -> 0
A53: =TEXT(Setup!$C$5+2,"dddd") -> Wednesday | B53: =Setup!$C$5+2 -> 46029 | C53: 12.30 - 13.00 | P53: =IFERROR(H53/Setup!$C$6,"") -> 0 | Q53: =IFERROR(H53-P53,"") -> 0
A54: =TEXT(Setup!$C$5+2,"dddd") -> Wednesday | B54: =Setup!$C$5+2 -> 46029 | C54: 13.00 - 13.30 | P54: =IFERROR(H54/Setup!$C$6,"") -> 0 | Q54: =IFERROR(H54-P54,"") -> 0
A55: =TEXT(Setup!$C$5+2,"dddd") -> Wednesday | B55: =Setup!$C$5+2 -> 46029 | C55: 13.30 - 14.00 | P55: =IFERROR(H55/Setup!$C$6,"") -> 0 | Q55: =IFERROR(H55-P55,"") -> 0
A56: =TEXT(Setup!$C$5+2,"dddd") -> Wednesday | B56: =Setup!$C$5+2 -> 46029 | C56: 14.00 - 14.30 | P56: =IFERROR(H56/Setup!$C$6,"") -> 0 | Q56: =IFERROR(H56-P56,"") -> 0
...

Sheet Wk2
A1: Day | B1: Date | C1: Time | D1: Customers In | E1: Sales | F1: Vouchers Used | G1: Walk In/Out | H1: Sale Amount | I1: Conversion | J1: Avg Sale | K1: Tracked Category | L1: Notes | M1: Cash | N1: vs Last Wk € | O1: vs Last Wk Cust | P1: Est. Cost | Q1: Est. Profit | R1: Last Year Day | S1: vs Last Year
A2: =TEXT(Setup!$C$5+7,"dddd") -> Monday | B2: =Setup!$C$5+7 -> 46034 | C2: 9.00 - 9.30 | P2: =IFERROR(H2/Setup!$C$6,"") -> 0 | Q2: =IFERROR(H2-P2,"") -> 0
A3: =TEXT(Setup!$C$5+7,"dddd") -> Monday | B3: =Setup!$C$5+7 -> 46034 | C3: 9.30 - 10.00 | P3: =IFERROR(H3/Setup!$C$6,"") -> 0 | Q3: =IFERROR(H3-P3,"") -> 0
A4: =TEXT(Setup!$C$5+7,"dddd") -> Monday | B4: =Setup!$C$5+7 -> 46034 | C4: 10.00 - 10.30 | P4: =IFERROR(H4/Setup!$C$6,"") -> 0 | Q4: =IFERROR(H4-P4,"") -> 0
A5: =TEXT(Setup!$C$5+7,"dddd") -> Monday | B5: =Setup!$C$5+7 -> 46034 | C5: 10.30 - 11.00 | P5: =IFERROR(H5/Setup!$C$6,"") -> 0 | Q5: =IFERROR(H5-P5,"") -> 0
A6: =TEXT(Setup!$C$5+7,"dddd") -> Monday | B6: =Setup!$C$5+7 -> 46034 | C6: 11.00 - 11.30 | P6: =IFERROR(H6/Setup!$C$6,"") -> 0 | Q6: =IFERROR(H6-P6,"") -> 0
A7: =TEXT(Setup!$C$5+7,"dddd") -> Monday | B7: =Setup!$C$5+7 -> 46034 | C7: 11.30 - 12.00 | P7: =IFERROR(H7/Setup!$C$6,"") -> 0 | Q7: =IFERROR(H7-P7,"") -> 0
A8: =TEXT(Setup!$C$5+7,"dddd") -> Monday | B8: =Setup!$C$5+7 -> 46034 | C8: 12.00 - 12.30 | P8: =IFERROR(H8/Setup!$C$6,"") -> 0 | Q8: =IFERROR(H8-P8,"") -> 0
A9: =TEXT(Setup!$C$5+7,"dddd") -> Monday | B9: =Setup!$C$5+7 -> 46034 | C9: 12.30 - 13.00 | P9: =IFERROR(H9/Setup!$C$6,"") -> 0 | Q9: =IFERROR(H9-P9,"") -> 0
A10: =TEXT(Setup!$C$5+7,"dddd") -> Monday | B10: =Setup!$C$5+7 -> 46034 | C10: 13.00 - 13.30 | P10: =IFERROR(H10/Setup!$C$6,"") -> 0 | Q10: =IFERROR(H10-P10,"") -> 0
A11: =TEXT(Setup!$C$5+7,"dddd") -> Monday | B11: =Setup!$C$5+7 -> 46034 | C11: 13.30 - 14.00 | P11: =IFERROR(H11/Setup!$C$6,"") -> 0 | Q11: =IFERROR(H11-P11,"") -> 0
A12: =TEXT(Setup!$C$5+7,"dddd") -> Monday | B12: =Setup!$C$5+7 -> 46034 | C12: 14.00 - 14.30 | P12: =IFERROR(H12/Setup!$C$6,"") -> 0 | Q12: =IFERROR(H12-P12,"") -> 0
A13: =TEXT(Setup!$C$5+7,"dddd") -> Monday | B13: =Setup!$C$5+7 -> 46034 | C13: 14.30 - 15.00 | P13: =IFERROR(H13/Setup!$C$6,"") -> 0 | Q13: =IFERROR(H13-P13,"") -> 0
... A22: =TEXT(Setup!$C$5+7,"dddd") -> Monday | B22: =Setup!$C$5+7 -> 46034 | C22: ONLINE | P22: =IFERROR(H22/Setup!$C$6,"") -> 0 | Q22: =IFERROR(H22-P22,"") -> 0
A23: =TEXT(Setup!$C$5+7,"dddd") -> Monday | B23: =Setup!$C$5+7 -> 46034 | C23: TOTAL | D23: =SUM(D2:D22) -> 0 | E23: =SUM(E2:E22) -> 0 | F23: =SUM(F2:F22) -> 0 | G23: =SUM(G2:G22) -> 0 | H23: =SUM(H2:H22) -> 0 | I23: =IFERROR(E23/D23,"") | J23: =IFERROR(H23/E23,"") | K23: =SUM(K2:K22) -> 0 | M23: =SUM(M2:M22) -> 0 | N23: =IFERROR(H23-Wk1!H23,"") -> 0 | O23: =IFERROR(D23-Wk1!D23,"") -> 0 | P23: =SUM(P2:P22) -> 0 | Q23: =SUM(Q2:Q22) -> 0 | R23: =IFERROR(INDEX('Last Year'!$C$6:$C$369,MATCH(B23-364,'Last Year'!$B$6:$B$369,0)),"") -> 0 | S23: =IFERROR(H23/R23-1,"")
A24: =TEXT(Setup!$C$5+8,"dddd") -> Tuesday | B24: =Setup!$C$5+8 -> 46035 | C24: 9.00 - 9.30 | P24: =IFERROR(H24/Setup!$C$6,"") -> 0 | Q24: =IFERROR(H24-P24,"") -> 0
A25: =TEXT(Setup!$C$5+8,"dddd") -> Tuesday | B25: =Setup!$C$5+8 -> 46035 | C25: 9.30 - 10.00 | P25: =IFERROR(H25/Setup!$C$6,"") -> 0 | Q25: =IFERROR(H25-P25,"") -> 0
A26: =TEXT(Setup!$C$5+8,"dddd") -> Tuesday | B26: =Setup!$C$5+8 -> 46035 | C26: 10.00 - 10.30 | P26: =IFERROR(H26/Setup!$C$6,"") -> 0 | Q26: =IFERROR(H26-P26,"") -> 0
A27: =TEXT(Setup!$C$5+8,"dddd") -> Tuesday | B27: =Setup!$C$5+8 -> 46035 | C27: 10.30 - 11.00 | P27: =IFERROR(H27/Setup!$C$6,"") -> 0 | Q27: =IFERROR(H27-P27,"") -> 0
A28: =TEXT(Setup!$C$5+8,"dddd") -> Tuesday | B28: =Setup!$C$5+8 -> 46035 | C28: 11.00 - 11.30 | P28: =IFERROR(H28/Setup!$C$6,"") -> 0 | Q28: =IFERROR(H28-P28,"") -> 0
A29: =TEXT(Setup!$C$5+8,"dddd") -> Tuesday | B29: =Setup!$C$5+8 -> 46035 | C29: 11.30 - 12.00 | P29: =IFERROR(H29/Setup!$C$6,"") -> 0 | Q29: =IFERROR(H29-P29,"") -> 0
A30: =TEXT(Setup!$C$5+8,"dddd") -> Tuesday | B30: =Setup!$C$5+8 -> 46035 | C30: 12.00 - 12.30 | P30: =IFERROR(H30/Setup!$C$6,"") -> 0 | Q30: =IFERROR(H30-P30,"") -> 0
A31: =TEXT(Setup!$C$5+8,"dddd") -> Tuesday | B31: =Setup!$C$5+8 -> 46035 | C31: 12.30 - 13.00 | P31: =IFERROR(H31/Setup!$C$6,"") -> 0 | Q31: =IFERROR(H31-P31,"") -> 0
A32: =TEXT(Setup!$C$5+8,"dddd") -> Tuesday | B32: =Setup!$C$5+8 -> 46035 | C32: 13.00 - 13.30 | P32: =IFERROR(H32/Setup!$C$6,"") -> 0 | Q32: =IFERROR(H32-P32,"") -> 0
A33: =TEXT(Setup!$C$5+8,"dddd") -> Tuesday | B33: =Setup!$C$5+8 -> 46035 | C33: 13.30 - 14.00 | P33: =IFERROR(H33/Setup!$C$6,"") -> 0 | Q33: =IFERROR(H33-P33,"") -> 0
A34: =TEXT(Setup!$C$5+8,"dddd") -> Tuesday | B34: =Setup!$C$5+8 -> 46035 | C34: 14.00 - 14.30 | P34: =IFERROR(H34/Setup!$C$6,"") -> 0 | Q34: =IFERROR(H34-P34,"") -> 0
A35: =TEXT(Setup!$C$5+8,"dddd") -> Tuesday | B35: =Setup!$C$5+8 -> 46035 | C35: 14.30 - 15.00 | P35: =IFERROR(H35/Setup!$C$6,"") -> 0 | Q35: =IFERROR(H35-P35,"") -> 0
... A44: =TEXT(Setup!$C$5+8,"dddd") -> Tuesday | B44: =Setup!$C$5+8 -> 46035 | C44: ONLINE | P44: =IFERROR(H44/Setup!$C$6,"") -> 0 | Q44: =IFERROR(H44-P44,"") -> 0
A45: =TEXT(Setup!$C$5+8,"dddd") -> Tuesday | B45: =Setup!$C$5+8 -> 46035 | C45: TOTAL | D45: =SUM(D24:D44) -> 0 | E45: =SUM(E24:E44) -> 0 | F45: =SUM(F24:F44) -> 0 | G45: =SUM(G24:G44) -> 0 | H45: =SUM(H24:H44) -> 0 | I45: =IFERROR(E45/D45,"") | J45: =IFERROR(H45/E45,"") | K45: =SUM(K24:K44) -> 0 | M45: =SUM(M24:M44) -> 0 | N45: =IFERROR(H45-Wk1!H45,"") -> 0 | O45: =IFERROR(D45-Wk1!D45,"") -> 0 | P45: =SUM(P24:P44) -> 0 | Q45: =SUM(Q24:Q44) -> 0 | R45: =IFERROR(INDEX('Last Year'!$C$6:$C$369,MATCH(B45-364,'Last Year'!$B$6:$B$369,0)),"") -> 0 | S45: =IFERROR(H45/R45-1,"")
A46: =TEXT(Setup!$C$5+9,"dddd") -> Wednesday | B46: =Setup!$C$5+9 -> 46036 | C46: 9.00 - 9.30 | P46: =IFERROR(H46/Setup!$C$6,"") -> 0 | Q46: =IFERROR(H46-P46,"") -> 0
A47: =TEXT(Setup!$C$5+9,"dddd") -> Wednesday | B47: =Setup!$C$5+9 -> 46036 | C47: 9.30 - 10.00 | P47: =IFERROR(H47/Setup!$C$6,"") -> 0 | Q47: =IFERROR(H47-P47,"") -> 0
A48: =TEXT(Setup!$C$5+9,"dddd") -> Wednesday | B48: =Setup!$C$5+9 -> 46036 | C48: 10.00 - 10.30 | P48: =IFERROR(H48/Setup!$C$6,"") -> 0 | Q48: =IFERROR(H48-P48,"") -> 0
A49: =TEXT(Setup!$C$5+9,"dddd") -> Wednesday | B49: =Setup!$C$5+9 -> 46036 | C49: 10.30 - 11.00 | P49: =IFERROR(H49/Setup!$C$6,"") -> 0 | Q49: =IFERROR(H49-P49,"") -> 0
A50: =TEXT(Setup!$C$5+9,"dddd") -> Wednesday | B50: =Setup!$C$5+9 -> 46036 | C50: 11.00 - 11.30 | P50: =IFERROR(H50/Setup!$C$6,"") -> 0 | Q50: =IFERROR(H50-P50,"") -> 0
A51: =TEXT(Setup!$C$5+9,"dddd") -> Wednesday | B51: =Setup!$C$5+9 -> 46036 | C51: 11.30 - 12.00 | P51: =IFERROR(H51/Setup!$C$6,"") -> 0 | Q51: =IFERROR(H51-P51,"") -> 0
A52: =TEXT(Setup!$C$5+9,"dddd") -> Wednesday | B52: =Setup!$C$5+9 -> 46036 | C52: 12.00 - 12.30 | P52: =IFERROR(H52/Setup!$C$6,"") -> 0 | Q52: =IFERROR(H52-P52,"") -> 0
A53: =TEXT(Setup!$C$5+9,"dddd") -> Wednesday | B53: =Setup!$C$5+9 -> 46036 | C53: 12.30 - 13.00 | P53: =IFERROR(H53/Setup!$C$6,"") -> 0 | Q53: =IFERROR(H53-P53,"") -> 0
A54: =TEXT(Setup!$C$5+9,"dddd") -> Wednesday | B54: =Setup!$C$5+9 -> 46036 | C54: 13.00 - 13.30 | P54: =IFERROR(H54/Setup!$C$6,"") -> 0 | Q54: =IFERROR(H54-P54,"") -> 0
A55: =TEXT(Setup!$C$5+9,"dddd") -> Wednesday | B55: =Setup!$C$5+9 -> 46036 | C55: 13.30 - 14.00 | P55: =IFERROR(H55/Setup!$C$6,"") -> 0 | Q55: =IFERROR(H55-P55,"") -> 0
A56: =TEXT(Setup!$C$5+9,"dddd") -> Wednesday | B56: =Setup!$C$5+9 -> 46036 | C56: 14.00 - 14.30 | P56: =IFERROR(H56/Setup!$C$6,"") -> 0 | Q56: =IFERROR(H56-P56,"") -> 0
...

Sheet Wk3
A1: Day | B1: Date | C1: Time | D1: Customers In | E1: Sales | F1: Vouchers Used | G1: Walk In/Out | H1: Sale Amount | I1: Conversion | J1: Avg Sale | K1: Tracked Category | L1: Notes | M1: Cash | N1: vs Last Wk € | O1: vs Last Wk Cust | P1: Est. Cost | Q1: Est. Profit | R1: Last Year Day | S1: vs Last Year
A2: =TEXT(Setup!$C$5+14,"dddd") -> Monday | B2: =Setup!$C$5+14 -> 46041 | C2: 9.00 - 9.30 | P2: =IFERROR(H2/Setup!$C$6,"") -> 0 | Q2: =IFERROR(H2-P2,"") -> 0
A3: =TEXT(Setup!$C$5+14,"dddd") -> Monday | B3: =Setup!$C$5+14 -> 46041 | C3: 9.30 - 10.00 | P3: =IFERROR(H3/Setup!$C$6,"") -> 0 | Q3: =IFERROR(H3-P3,"") -> 0
A4: =TEXT(Setup!$C$5+14,"dddd") -> Monday | B4: =Setup!$C$5+14 -> 46041 | C4: 10.00 - 10.30 | P4: =IFERROR(H4/Setup!$C$6,"") -> 0 | Q4: =IFERROR(H4-P4,"") -> 0
A5: =TEXT(Setup!$C$5+14,"dddd") -> Monday | B5: =Setup!$C$5+14 -> 46041 | C5: 10.30 - 11.00 | P5: =IFERROR(H5/Setup!$C$6,"") -> 0 | Q5: =IFERROR(H5-P5,"") -> 0
A6: =TEXT(Setup!$C$5+14,"dddd") -> Monday | B6: =Setup!$C$5+14 -> 46041 | C6: 11.00 - 11.30 | P6: =IFERROR(H6/Setup!$C$6,"") -> 0 | Q6: =IFERROR(H6-P6,"") -> 0
A7: =TEXT(Setup!$C$5+14,"dddd") -> Monday | B7: =Setup!$C$5+14 -> 46041 | C7: 11.30 - 12.00 | P7: =IFERROR(H7/Setup!$C$6,"") -> 0 | Q7: =IFERROR(H7-P7,"") -> 0
A8: =TEXT(Setup!$C$5+14,"dddd") -> Monday | B8: =Setup!$C$5+14 -> 46041 | C8: 12.00 - 12.30 | P8: =IFERROR(H8/Setup!$C$6,"") -> 0 | Q8: =IFERROR(H8-P8,"") -> 0
A9: =TEXT(Setup!$C$5+14,"dddd") -> Monday | B9: =Setup!$C$5+14 -> 46041 | C9: 12.30 - 13.00 | P9: =IFERROR(H9/Setup!$C$6,"") -> 0 | Q9: =IFERROR(H9-P9,"") -> 0
A10: =TEXT(Setup!$C$5+14,"dddd") -> Monday | B10: =Setup!$C$5+14 -> 46041 | C10: 13.00 - 13.30 | P10: =IFERROR(H10/Setup!$C$6,"") -> 0 | Q10: =IFERROR(H10-P10,"") -> 0
A11: =TEXT(Setup!$C$5+14,"dddd") -> Monday | B11: =Setup!$C$5+14 -> 46041 | C11: 13.30 - 14.00 | P11: =IFERROR(H11/Setup!$C$6,"") -> 0 | Q11: =IFERROR(H11-P11,"") -> 0
A12: =TEXT(Setup!$C$5+14,"dddd") -> Monday | B12: =Setup!$C$5+14 -> 46041 | C12: 14.00 - 14.30 | P12: =IFERROR(H12/Setup!$C$6,"") -> 0 | Q12: =IFERROR(H12-P12,"") -> 0
A13: =TEXT(Setup!$C$5+14,"dddd") -> Monday | B13: =Setup!$C$5+14 -> 46041 | C13: 14.30 - 15.00 | P13: =IFERROR(H13/Setup!$C$6,"") -> 0 | Q13: =IFERROR(H13-P13,"") -> 0
... A22: =TEXT(Setup!$C$5+14,"dddd") -> Monday | B22: =Setup!$C$5+14 -> 46041 | C22: ONLINE | P22: =IFERROR(H22/Setup!$C$6,"") -> 0 | Q22: =IFERROR(H22-P22,"") -> 0
A23: =TEXT(Setup!$C$5+14,"dddd") -> Monday | B23: =Setup!$C$5+14 -> 46041 | C23: TOTAL | D23: =SUM(D2:D22) -> 0 | E23: =SUM(E2:E22) -> 0 | F23: =SUM(F2:F22) -> 0 | G23: =SUM(G2:G22) -> 0 | H23: =SUM(H2:H22) -> 0 | I23: =IFERROR(E23/D23,"") | J23: =IFERROR(H23/E23,"") | K23: =SUM(K2:K22) -> 0 | M23: =SUM(M2:M22) -> 0 | N23: =IFERROR(H23-Wk2!H23,"") -> 0 | O23: =IFERROR(D23-Wk2!D23,"") -> 0 | P23: =SUM(P2:P22) -> 0 | Q23: =SUM(Q2:Q22) -> 0 | R23: =IFERROR(INDEX('Last Year'!$C$6:$C$369,MATCH(B23-364,'Last Year'!$B$6:$B$369,0)),"") -> 0 | S23: =IFERROR(H23/R23-1,"")
A24: =TEXT(Setup!$C$5+15,"dddd") -> Tuesday | B24: =Setup!$C$5+15 -> 46042 | C24: 9.00 - 9.30 | P24: =IFERROR(H24/Setup!$C$6,"") -> 0 | Q24: =IFERROR(H24-P24,"") -> 0
A25: =TEXT(Setup!$C$5+15,"dddd") -> Tuesday | B25: =Setup!$C$5+15 -> 46042 | C25: 9.30 - 10.00 | P25: =IFERROR(H25/Setup!$C$6,"") -> 0 | Q25: =IFERROR(H25-P25,"") -> 0
A26: =TEXT(Setup!$C$5+15,"dddd") -> Tuesday | B26: =Setup!$C$5+15 -> 46042 | C26: 10.00 - 10.30 | P26: =IFERROR(H26/Setup!$C$6,"") -> 0 | Q26: =IFERROR(H26-P26,"") -> 0
A27: =TEXT(Setup!$C$5+15,"dddd") -> Tuesday | B27: =Setup!$C$5+15 -> 46042 | C27: 10.30 - 11.00 | P27: =IFERROR(H27/Setup!$C$6,"") -> 0 | Q27: =IFERROR(H27-P27,"") -> 0
A28: =TEXT(Setup!$C$5+15,"dddd") -> Tuesday | B28: =Setup!$C$5+15 -> 46042 | C28: 11.00 - 11.30 | P28: =IFERROR(H28/Setup!$C$6,"") -> 0 | Q28: =IFERROR(H28-P28,"") -> 0
A29: =TEXT(Setup!$C$5+15,"dddd") -> Tuesday | B29: =Setup!$C$5+15 -> 46042 | C29: 11.30 - 12.00 | P29: =IFERROR(H29/Setup!$C$6,"") -> 0 | Q29: =IFERROR(H29-P29,"") -> 0
A30: =TEXT(Setup!$C$5+15,"dddd") -> Tuesday | B30: =Setup!$C$5+15 -> 46042 | C30: 12.00 - 12.30 | P30: =IFERROR(H30/Setup!$C$6,"") -> 0 | Q30: =IFERROR(H30-P30,"") -> 0
A31: =TEXT(Setup!$C$5+15,"dddd") -> Tuesday | B31: =Setup!$C$5+15 -> 46042 | C31: 12.30 - 13.00 | P31: =IFERROR(H31/Setup!$C$6,"") -> 0 | Q31: =IFERROR(H31-P31,"") -> 0
A32: =TEXT(Setup!$C$5+15,"dddd") -> Tuesday | B32: =Setup!$C$5+15 -> 46042 | C32: 13.00 - 13.30 | P32: =IFERROR(H32/Setup!$C$6,"") -> 0 | Q32: =IFERROR(H32-P32,"") -> 0
A33: =TEXT(Setup!$C$5+15,"dddd") -> Tuesday | B33: =Setup!$C$5+15 -> 46042 | C33: 13.30 - 14.00 | P33: =IFERROR(H33/Setup!$C$6,"") -> 0 | Q33: =IFERROR(H33-P33,"") -> 0
A34: =TEXT(Setup!$C$5+15,"dddd") -> Tuesday | B34: =Setup!$C$5+15 -> 46042 | C34: 14.00 - 14.30 | P34: =IFERROR(H34/Setup!$C$6,"") -> 0 | Q34: =IFERROR(H34-P34,"") -> 0
A35: =TEXT(Setup!$C$5+15,"dddd") -> Tuesday | B35: =Setup!$C$5+15 -> 46042 | C35: 14.30 - 15.00 | P35: =IFERROR(H35/Setup!$C$6,"") -> 0 | Q35: =IFERROR(H35-P35,"") -> 0
... A44: =TEXT(Setup!$C$5+15,"dddd") -> Tuesday | B44: =Setup!$C$5+15 -> 46042 | C44: ONLINE | P44: =IFERROR(H44/Setup!$C$6,"") -> 0 | Q44: =IFERROR(H44-P44,"") -> 0
A45: =TEXT(Setup!$C$5+15,"dddd") -> Tuesday | B45: =Setup!$C$5+15 -> 46042 | C45: TOTAL | D45: =SUM(D24:D44) -> 0 | E45: =SUM(E24:E44) -> 0 | F45: =SUM(F24:F44) -> 0 | G45: =SUM(G24:G44) -> 0 | H45: =SUM(H24:H44) -> 0 | I45: =IFERROR(E45/D45,"") | J45: =IFERROR(H45/E45,"") | K45: =SUM(K24:K44) -> 0 | M45: =SUM(M24:M44) -> 0 | N45: =IFERROR(H45-Wk2!H45,"") -> 0 | O45: =IFERROR(D45-Wk2!D45,"") -> 0 | P45: =SUM(P24:P44) -> 0 | Q45: =SUM(Q24:Q44) -> 0 | R45: =IFERROR(INDEX('Last Year'!$C$6:$C$369,MATCH(B45-364,'Last Year'!$B$6:$B$369,0)),"") -> 0 | S45: =IFERROR(H45/R45-1,"")
A46: =TEXT(Setup!$C$5+16,"dddd") -> Wednesday | B46: =Setup!$C$5+16 -> 46043 | C46: 9.00 - 9.30 | P46: =IFERROR(H46/Setup!$C$6,"") -> 0 | Q46: =IFERROR(H46-P46,"") -> 0
A47: =TEXT(Setup!$C$5+16,"dddd") -> Wednesday | B47: =Setup!$C$5+16 -> 46043 | C47: 9.30 - 10.00 | P47: =IFERROR(H47/Setup!$C$6,"") -> 0 | Q47: =IFERROR(H47-P47,"") -> 0
A48: =TEXT(Setup!$C$5+16,"dddd") -> Wednesday | B48: =Setup!$C$5+16 -> 46043 | C48: 10.00 - 10.30 | P48: =IFERROR(H48/Setup!$C$6,"") -> 0 | Q48: =IFERROR(H48-P48,"") -> 0
A49: =TEXT(Setup!$C$5+16,"dddd") -> Wednesday | B49: =Setup!$C$5+16 -> 46043 | C49: 10.30 - 11.00 | P49: =IFERROR(H49/Setup!$C$6,"") -> 0 | Q49: =IFERROR(H49-P49,"") -> 0
A50: =TEXT(Setup!$C$5+16,"dddd") -> Wednesday | B50: =Setup!$C$5+16 -> 46043 | C50: 11.00 - 11.30 | P50: =IFERROR(H50/Setup!$C$6,"") -> 0 | Q50: =IFERROR(H50-P50,"") -> 0
A51: =TEXT(Setup!$C$5+16,"dddd") -> Wednesday | B51: =Setup!$C$5+16 -> 46043 | C51: 11.30 - 12.00 | P51: =IFERROR(H51/Setup!$C$6,"") -> 0 | Q51: =IFERROR(H51-P51,"") -> 0
A52: =TEXT(Setup!$C$5+16,"dddd") -> Wednesday | B52: =Setup!$C$5+16 -> 46043 | C52: 12.00 - 12.30 | P52: =IFERROR(H52/Setup!$C$6,"") -> 0 | Q52: =IFERROR(H52-P52,"") -> 0
A53: =TEXT(Setup!$C$5+16,"dddd") -> Wednesday | B53: =Setup!$C$5+16 -> 46043 | C53: 12.30 - 13.00 | P53: =IFERROR(H53/Setup!$C$6,"") -> 0 | Q53: =IFERROR(H53-P53,"") -> 0
A54: =TEXT(Setup!$C$5+16,"dddd") -> Wednesday | B54: =Setup!$C$5+16 -> 46043 | C54: 13.00 - 13.30 | P54: =IFERROR(H54/Setup!$C$6,"") -> 0 | Q54: =IFERROR(H54-P54,"") -> 0
A55: =TEXT(Setup!$C$5+16,"dddd") -> Wednesday | B55: =Setup!$C$5+16 -> 46043 | C55: 13.30 - 14.00 | P55: =IFERROR(H55/Setup!$C$6,"") -> 0 | Q55: =IFERROR(H55-P55,"") -> 0
A56: =TEXT(Setup!$C$5+16,"dddd") -> Wednesday | B56: =Setup!$C$5+16 -> 46043 | C56: 14.00 - 14.30 | P56: =IFERROR(H56/Setup!$C$6,"") -> 0 | Q56: =IFERROR(H56-P56,"") -> 0
...

Sheet Wk4
A1: Day | B1: Date | C1: Time | D1: Customers In | E1: Sales | F1: Vouchers Used | G1: Walk In/Out | H1: Sale Amount | I1: Conversion | J1: Avg Sale | K1: Tracked Category | L1: Notes | M1: Cash | N1: vs Last Wk € | O1: vs Last Wk Cust | P1: Est. Cost | Q1: Est. Profit | R1: Last Year Day | S1: vs Last Year
A2: =TEXT(Setup!$C$5+21,"dddd") -> Monday | B2: =Setup!$C$5+21 -> 46048 | C2: 9.00 - 9.30 | P2: =IFERROR(H2/Setup!$C$6,"") -> 0 | Q2: =IFERROR(H2-P2,"") -> 0
A3: =TEXT(Setup!$C$5+21,"dddd") -> Monday | B3: =Setup!$C$5+21 -> 46048 | C3: 9.30 - 10.00 | P3: =IFERROR(H3/Setup!$C$6,"") -> 0 | Q3: =IFERROR(H3-P3,"") -> 0
A4: =TEXT(Setup!$C$5+21,"dddd") -> Monday | B4: =Setup!$C$5+21 -> 46048 | C4: 10.00 - 10.30 | P4: =IFERROR(H4/Setup!$C$6,"") -> 0 | Q4: =IFERROR(H4-P4,"") -> 0
A5: =TEXT(Setup!$C$5+21,"dddd") -> Monday | B5: =Setup!$C$5+21 -> 46048 | C5: 10.30 - 11.00 | P5: =IFERROR(H5/Setup!$C$6,"") -> 0 | Q5: =IFERROR(H5-P5,"") -> 0
A6: =TEXT(Setup!$C$5+21,"dddd") -> Monday | B6: =Setup!$C$5+21 -> 46048 | C6: 11.00 - 11.30 | P6: =IFERROR(H6/Setup!$C$6,"") -> 0 | Q6: =IFERROR(H6-P6,"") -> 0
A7: =TEXT(Setup!$C$5+21,"dddd") -> Monday | B7: =Setup!$C$5+21 -> 46048 | C7: 11.30 - 12.00 | P7: =IFERROR(H7/Setup!$C$6,"") -> 0 | Q7: =IFERROR(H7-P7,"") -> 0
A8: =TEXT(Setup!$C$5+21,"dddd") -> Monday | B8: =Setup!$C$5+21 -> 46048 | C8: 12.00 - 12.30 | P8: =IFERROR(H8/Setup!$C$6,"") -> 0 | Q8: =IFERROR(H8-P8,"") -> 0
A9: =TEXT(Setup!$C$5+21,"dddd") -> Monday | B9: =Setup!$C$5+21 -> 46048 | C9: 12.30 - 13.00 | P9: =IFERROR(H9/Setup!$C$6,"") -> 0 | Q9: =IFERROR(H9-P9,"") -> 0
A10: =TEXT(Setup!$C$5+21,"dddd") -> Monday | B10: =Setup!$C$5+21 -> 46048 | C10: 13.00 - 13.30 | P10: =IFERROR(H10/Setup!$C$6,"") -> 0 | Q10: =IFERROR(H10-P10,"") -> 0
A11: =TEXT(Setup!$C$5+21,"dddd") -> Monday | B11: =Setup!$C$5+21 -> 46048 | C11: 13.30 - 14.00 | P11: =IFERROR(H11/Setup!$C$6,"") -> 0 | Q11: =IFERROR(H11-P11,"") -> 0
A12: =TEXT(Setup!$C$5+21,"dddd") -> Monday | B12: =Setup!$C$5+21 -> 46048 | C12: 14.00 - 14.30 | P12: =IFERROR(H12/Setup!$C$6,"") -> 0 | Q12: =IFERROR(H12-P12,"") -> 0
A13: =TEXT(Setup!$C$5+21,"dddd") -> Monday | B13: =Setup!$C$5+21 -> 46048 | C13: 14.30 - 15.00 | P13: =IFERROR(H13/Setup!$C$6,"") -> 0 | Q13: =IFERROR(H13-P13,"") -> 0
... A22: =TEXT(Setup!$C$5+21,"dddd") -> Monday | B22: =Setup!$C$5+21 -> 46048 | C22: ONLINE | P22: =IFERROR(H22/Setup!$C$6,"") -> 0 | Q22: =IFERROR(H22-P22,"") -> 0
A23: =TEXT(Setup!$C$5+21,"dddd") -> Monday | B23: =Setup!$C$5+21 -> 46048 | C23: TOTAL | D23: =SUM(D2:D22) -> 0 | E23: =SUM(E2:E22) -> 0 | F23: =SUM(F2:F22) -> 0 | G23: =SUM(G2:G22) -> 0 | H23: =SUM(H2:H22) -> 0 | I23: =IFERROR(E23/D23,"") | J23: =IFERROR(H23/E23,"") | K23: =SUM(K2:K22) -> 0 | M23: =SUM(M2:M22) -> 0 | N23: =IFERROR(H23-Wk3!H23,"") -> 0 | O23: =IFERROR(D23-Wk3!D23,"") -> 0 | P23: =SUM(P2:P22) -> 0 | Q23: =SUM(Q2:Q22) -> 0 | R23: =IFERROR(INDEX('Last Year'!$C$6:$C$369,MATCH(B23-364,'Last Year'!$B$6:$B$369,0)),"") -> 0 | S23: =IFERROR(H23/R23-1,"")
A24: =TEXT(Setup!$C$5+22,"dddd") -> Tuesday | B24: =Setup!$C$5+22 -> 46049 | C24: 9.00 - 9.30 | P24: =IFERROR(H24/Setup!$C$6,"") -> 0 | Q24: =IFERROR(H24-P24,"") -> 0
A25: =TEXT(Setup!$C$5+22,"dddd") -> Tuesday | B25: =Setup!$C$5+22 -> 46049 | C25: 9.30 - 10.00 | P25: =IFERROR(H25/Setup!$C$6,"") -> 0 | Q25: =IFERROR(H25-P25,"") -> 0
A26: =TEXT(Setup!$C$5+22,"dddd") -> Tuesday | B26: =Setup!$C$5+22 -> 46049 | C26: 10.00 - 10.30 | P26: =IFERROR(H26/Setup!$C$6,"") -> 0 | Q26: =IFERROR(H26-P26,"") -> 0
A27: =TEXT(Setup!$C$5+22,"dddd") -> Tuesday | B27: =Setup!$C$5+22 -> 46049 | C27: 10.30 - 11.00 | P27: =IFERROR(H27/Setup!$C$6,"") -> 0 | Q27: =IFERROR(H27-P27,"") -> 0
A28: =TEXT(Setup!$C$5+22,"dddd") -> Tuesday | B28: =Setup!$C$5+22 -> 46049 | C28: 11.00 - 11.30 | P28: =IFERROR(H28/Setup!$C$6,"") -> 0 | Q28: =IFERROR(H28-P28,"") -> 0
A29: =TEXT(Setup!$C$5+22,"dddd") -> Tuesday | B29: =Setup!$C$5+22 -> 46049 | C29: 11.30 - 12.00 | P29: =IFERROR(H29/Setup!$C$6,"") -> 0 | Q29: =IFERROR(H29-P29,"") -> 0
A30: =TEXT(Setup!$C$5+22,"dddd") -> Tuesday | B30: =Setup!$C$5+22 -> 46049 | C30: 12.00 - 12.30 | P30: =IFERROR(H30/Setup!$C$6,"") -> 0 | Q30: =IFERROR(H30-P30,"") -> 0
A31: =TEXT(Setup!$C$5+22,"dddd") -> Tuesday | B31: =Setup!$C$5+22 -> 46049 | C31: 12.30 - 13.00 | P31: =IFERROR(H31/Setup!$C$6,"") -> 0 | Q31: =IFERROR(H31-P31,"") -> 0
A32: =TEXT(Setup!$C$5+22,"dddd") -> Tuesday | B32: =Setup!$C$5+22 -> 46049 | C32: 13.00 - 13.30 | P32: =IFERROR(H32/Setup!$C$6,"") -> 0 | Q32: =IFERROR(H32-P32,"") -> 0
A33: =TEXT(Setup!$C$5+22,"dddd") -> Tuesday | B33: =Setup!$C$5+22 -> 46049 | C33: 13.30 - 14.00 | P33: =IFERROR(H33/Setup!$C$6,"") -> 0 | Q33: =IFERROR(H33-P33,"") -> 0
A34: =TEXT(Setup!$C$5+22,"dddd") -> Tuesday | B34: =Setup!$C$5+22 -> 46049 | C34: 14.00 - 14.30 | P34: =IFERROR(H34/Setup!$C$6,"") -> 0 | Q34: =IFERROR(H34-P34,"") -> 0
A35: =TEXT(Setup!$C$5+22,"dddd") -> Tuesday | B35: =Setup!$C$5+22 -> 46049 | C35: 14.30 - 15.00 | P35: =IFERROR(H35/Setup!$C$6,"") -> 0 | Q35: =IFERROR(H35-P35,"") -> 0
... A44: =TEXT(Setup!$C$5+22,"dddd") -> Tuesday | B44: =Setup!$C$5+22 -> 46049 | C44: ONLINE | P44: =IFERROR(H44/Setup!$C$6,"") -> 0 | Q44: =IFERROR(H44-P44,"") -> 0
A45: =TEXT(Setup!$C$5+22,"dddd") -> Tuesday | B45: =Setup!$C$5+22 -> 46049 | C45: TOTAL | D45: =SUM(D24:D44) -> 0 | E45: =SUM(E24:E44) -> 0 | F45: =SUM(F24:F44) -> 0 | G45: =SUM(G24:G44) -> 0 | H45: =SUM(H24:H44) -> 0 | I45: =IFERROR(E45/D45,"") | J45: =IFERROR(H45/E45,"") | K45: =SUM(K24:K44) -> 0 | M45: =SUM(M24:M44) -> 0 | N45: =IFERROR(H45-Wk3!H45,"") -> 0 | O45: =IFERROR(D45-Wk3!D45,"") -> 0 | P45: =SUM(P24:P44) -> 0 | Q45: =SUM(Q24:Q44) -> 0 | R45: =IFERROR(INDEX('Last Year'!$C$6:$C$369,MATCH(B45-364,'Last Year'!$B$6:$B$369,0)),"") -> 0 | S45: =IFERROR(H45/R45-1,"")
A46: =TEXT(Setup!$C$5+23,"dddd") -> Wednesday | B46: =Setup!$C$5+23 -> 46050 | C46: 9.00 - 9.30 | P46: =IFERROR(H46/Setup!$C$6,"") -> 0 | Q46: =IFERROR(H46-P46,"") -> 0
A47: =TEXT(Setup!$C$5+23,"dddd") -> Wednesday | B47: =Setup!$C$5+23 -> 46050 | C47: 9.30 - 10.00 | P47: =IFERROR(H47/Setup!$C$6,"") -> 0 | Q47: =IFERROR(H47-P47,"") -> 0
A48: =TEXT(Setup!$C$5+23,"dddd") -> Wednesday | B48: =Setup!$C$5+23 -> 46050 | C48: 10.00 - 10.30 | P48: =IFERROR(H48/Setup!$C$6,"") -> 0 | Q48: =IFERROR(H48-P48,"") -> 0
A49: =TEXT(Setup!$C$5+23,"dddd") -> Wednesday | B49: =Setup!$C$5+23 -> 46050 | C49: 10.30 - 11.00 | P49: =IFERROR(H49/Setup!$C$6,"") -> 0 | Q49: =IFERROR(H49-P49,"") -> 0
A50: =TEXT(Setup!$C$5+23,"dddd") -> Wednesday | B50: =Setup!$C$5+23 -> 46050 | C50: 11.00 - 11.30 | P50: =IFERROR(H50/Setup!$C$6,"") -> 0 | Q50: =IFERROR(H50-P50,"") -> 0
A51: =TEXT(Setup!$C$5+23,"dddd") -> Wednesday | B51: =Setup!$C$5+23 -> 46050 | C51: 11.30 - 12.00 | P51: =IFERROR(H51/Setup!$C$6,"") -> 0 | Q51: =IFERROR(H51-P51,"") -> 0
A52: =TEXT(Setup!$C$5+23,"dddd") -> Wednesday | B52: =Setup!$C$5+23 -> 46050 | C52: 12.00 - 12.30 | P52: =IFERROR(H52/Setup!$C$6,"") -> 0 | Q52: =IFERROR(H52-P52,"") -> 0
A53: =TEXT(Setup!$C$5+23,"dddd") -> Wednesday | B53: =Setup!$C$5+23 -> 46050 | C53: 12.30 - 13.00 | P53: =IFERROR(H53/Setup!$C$6,"") -> 0 | Q53: =IFERROR(H53-P53,"") -> 0
A54: =TEXT(Setup!$C$5+23,"dddd") -> Wednesday | B54: =Setup!$C$5+23 -> 46050 | C54: 13.00 - 13.30 | P54: =IFERROR(H54/Setup!$C$6,"") -> 0 | Q54: =IFERROR(H54-P54,"") -> 0
A55: =TEXT(Setup!$C$5+23,"dddd") -> Wednesday | B55: =Setup!$C$5+23 -> 46050 | C55: 13.30 - 14.00 | P55: =IFERROR(H55/Setup!$C$6,"") -> 0 | Q55: =IFERROR(H55-P55,"") -> 0
A56: =TEXT(Setup!$C$5+23,"dddd") -> Wednesday | B56: =Setup!$C$5+23 -> 46050 | C56: 14.00 - 14.30 | P56: =IFERROR(H56/Setup!$C$6,"") -> 0 | Q56: =IFERROR(H56-P56,"") -> 0
...

Sheet Wk5
A1: Day | B1: Date | C1: Time | D1: Customers In | E1: Sales | F1: Vouchers Used | G1: Walk In/Out | H1: Sale Amount | I1: Conversion | J1: Avg Sale | K1: Tracked Category | L1: Notes | M1: Cash | N1: vs Last Wk € | O1: vs Last Wk Cust | P1: Est. Cost | Q1: Est. Profit | R1: Last Year Day | S1: vs Last Year
A2: =TEXT(Setup!$C$5+28,"dddd") -> Monday | B2: =Setup!$C$5+28 -> 46055 | C2: 9.00 - 9.30 | P2: =IFERROR(H2/Setup!$C$6,"") -> 0 | Q2: =IFERROR(H2-P2,"") -> 0
A3: =TEXT(Setup!$C$5+28,"dddd") -> Monday | B3: =Setup!$C$5+28 -> 46055 | C3: 9.30 - 10.00 | P3: =IFERROR(H3/Setup!$C$6,"") -> 0 | Q3: =IFERROR(H3-P3,"") -> 0
A4: =TEXT(Setup!$C$5+28,"dddd") -> Monday | B4: =Setup!$C$5+28 -> 46055 | C4: 10.00 - 10.30 | P4: =IFERROR(H4/Setup!$C$6,"") -> 0 | Q4: =IFERROR(H4-P4,"") -> 0
A5: =TEXT(Setup!$C$5+28,"dddd") -> Monday | B5: =Setup!$C$5+28 -> 46055 | C5: 10.30 - 11.00 | P5: =IFERROR(H5/Setup!$C$6,"") -> 0 | Q5: =IFERROR(H5-P5,"") -> 0
A6: =TEXT(Setup!$C$5+28,"dddd") -> Monday | B6: =Setup!$C$5+28 -> 46055 | C6: 11.00 - 11.30 | P6: =IFERROR(H6/Setup!$C$6,"") -> 0 | Q6: =IFERROR(H6-P6,"") -> 0
A7: =TEXT(Setup!$C$5+28,"dddd") -> Monday | B7: =Setup!$C$5+28 -> 46055 | C7: 11.30 - 12.00 | P7: =IFERROR(H7/Setup!$C$6,"") -> 0 | Q7: =IFERROR(H7-P7,"") -> 0
A8: =TEXT(Setup!$C$5+28,"dddd") -> Monday | B8: =Setup!$C$5+28 -> 46055 | C8: 12.00 - 12.30 | P8: =IFERROR(H8/Setup!$C$6,"") -> 0 | Q8: =IFERROR(H8-P8,"") -> 0
A9: =TEXT(Setup!$C$5+28,"dddd") -> Monday | B9: =Setup!$C$5+28 -> 46055 | C9: 12.30 - 13.00 | P9: =IFERROR(H9/Setup!$C$6,"") -> 0 | Q9: =IFERROR(H9-P9,"") -> 0
A10: =TEXT(Setup!$C$5+28,"dddd") -> Monday | B10: =Setup!$C$5+28 -> 46055 | C10: 13.00 - 13.30 | P10: =IFERROR(H10/Setup!$C$6,"") -> 0 | Q10: =IFERROR(H10-P10,"") -> 0
A11: =TEXT(Setup!$C$5+28,"dddd") -> Monday | B11: =Setup!$C$5+28 -> 46055 | C11: 13.30 - 14.00 | P11: =IFERROR(H11/Setup!$C$6,"") -> 0 | Q11: =IFERROR(H11-P11,"") -> 0
A12: =TEXT(Setup!$C$5+28,"dddd") -> Monday | B12: =Setup!$C$5+28 -> 46055 | C12: 14.00 - 14.30 | P12: =IFERROR(H12/Setup!$C$6,"") -> 0 | Q12: =IFERROR(H12-P12,"") -> 0
A13: =TEXT(Setup!$C$5+28,"dddd") -> Monday | B13: =Setup!$C$5+28 -> 46055 | C13: 14.30 - 15.00 | P13: =IFERROR(H13/Setup!$C$6,"") -> 0 | Q13: =IFERROR(H13-P13,"") -> 0
... A22: =TEXT(Setup!$C$5+28,"dddd") -> Monday | B22: =Setup!$C$5+28 -> 46055 | C22: ONLINE | P22: =IFERROR(H22/Setup!$C$6,"") -> 0 | Q22: =IFERROR(H22-P22,"") -> 0
A23: =TEXT(Setup!$C$5+28,"dddd") -> Monday | B23: =Setup!$C$5+28 -> 46055 | C23: TOTAL | D23: =SUM(D2:D22) -> 0 | E23: =SUM(E2:E22) -> 0 | F23: =SUM(F2:F22) -> 0 | G23: =SUM(G2:G22) -> 0 | H23: =SUM(H2:H22) -> 0 | I23: =IFERROR(E23/D23,"") | J23: =IFERROR(H23/E23,"") | K23: =SUM(K2:K22) -> 0 | M23: =SUM(M2:M22) -> 0 | N23: =IFERROR(H23-Wk4!H23,"") -> 0 | O23: =IFERROR(D23-Wk4!D23,"") -> 0 | P23: =SUM(P2:P22) -> 0 | Q23: =SUM(Q2:Q22) -> 0 | R23: =IFERROR(INDEX('Last Year'!$C$6:$C$369,MATCH(B23-364,'Last Year'!$B$6:$B$369,0)),"") -> 0 | S23: =IFERROR(H23/R23-1,"")
A24: =TEXT(Setup!$C$5+29,"dddd") -> Tuesday | B24: =Setup!$C$5+29 -> 46056 | C24: 9.00 - 9.30 | P24: =IFERROR(H24/Setup!$C$6,"") -> 0 | Q24: =IFERROR(H24-P24,"") -> 0
A25: =TEXT(Setup!$C$5+29,"dddd") -> Tuesday | B25: =Setup!$C$5+29 -> 46056 | C25: 9.30 - 10.00 | P25: =IFERROR(H25/Setup!$C$6,"") -> 0 | Q25: =IFERROR(H25-P25,"") -> 0
A26: =TEXT(Setup!$C$5+29,"dddd") -> Tuesday | B26: =Setup!$C$5+29 -> 46056 | C26: 10.00 - 10.30 | P26: =IFERROR(H26/Setup!$C$6,"") -> 0 | Q26: =IFERROR(H26-P26,"") -> 0
A27: =TEXT(Setup!$C$5+29,"dddd") -> Tuesday | B27: =Setup!$C$5+29 -> 46056 | C27: 10.30 - 11.00 | P27: =IFERROR(H27/Setup!$C$6,"") -> 0 | Q27: =IFERROR(H27-P27,"") -> 0
A28: =TEXT(Setup!$C$5+29,"dddd") -> Tuesday | B28: =Setup!$C$5+29 -> 46056 | C28: 11.00 - 11.30 | P28: =IFERROR(H28/Setup!$C$6,"") -> 0 | Q28: =IFERROR(H28-P28,"") -> 0
A29: =TEXT(Setup!$C$5+29,"dddd") -> Tuesday | B29: =Setup!$C$5+29 -> 46056 | C29: 11.30 - 12.00 | P29: =IFERROR(H29/Setup!$C$6,"") -> 0 | Q29: =IFERROR(H29-P29,"") -> 0
A30: =TEXT(Setup!$C$5+29,"dddd") -> Tuesday | B30: =Setup!$C$5+29 -> 46056 | C30: 12.00 - 12.30 | P30: =IFERROR(H30/Setup!$C$6,"") -> 0 | Q30: =IFERROR(H30-P30,"") -> 0
A31: =TEXT(Setup!$C$5+29,"dddd") -> Tuesday | B31: =Setup!$C$5+29 -> 46056 | C31: 12.30 - 13.00 | P31: =IFERROR(H31/Setup!$C$6,"") -> 0 | Q31: =IFERROR(H31-P31,"") -> 0
A32: =TEXT(Setup!$C$5+29,"dddd") -> Tuesday | B32: =Setup!$C$5+29 -> 46056 | C32: 13.00 - 13.30 | P32: =IFERROR(H32/Setup!$C$6,"") -> 0 | Q32: =IFERROR(H32-P32,"") -> 0
A33: =TEXT(Setup!$C$5+29,"dddd") -> Tuesday | B33: =Setup!$C$5+29 -> 46056 | C33: 13.30 - 14.00 | P33: =IFERROR(H33/Setup!$C$6,"") -> 0 | Q33: =IFERROR(H33-P33,"") -> 0
A34: =TEXT(Setup!$C$5+29,"dddd") -> Tuesday | B34: =Setup!$C$5+29 -> 46056 | C34: 14.00 - 14.30 | P34: =IFERROR(H34/Setup!$C$6,"") -> 0 | Q34: =IFERROR(H34-P34,"") -> 0
A35: =TEXT(Setup!$C$5+29,"dddd") -> Tuesday | B35: =Setup!$C$5+29 -> 46056 | C35: 14.30 - 15.00 | P35: =IFERROR(H35/Setup!$C$6,"") -> 0 | Q35: =IFERROR(H35-P35,"") -> 0
... A44: =TEXT(Setup!$C$5+29,"dddd") -> Tuesday | B44: =Setup!$C$5+29 -> 46056 | C44: ONLINE | P44: =IFERROR(H44/Setup!$C$6,"") -> 0 | Q44: =IFERROR(H44-P44,"") -> 0
A45: =TEXT(Setup!$C$5+29,"dddd") -> Tuesday | B45: =Setup!$C$5+29 -> 46056 | C45: TOTAL | D45: =SUM(D24:D44) -> 0 | E45: =SUM(E24:E44) -> 0 | F45: =SUM(F24:F44) -> 0 | G45: =SUM(G24:G44) -> 0 | H45: =SUM(H24:H44) -> 0 | I45: =IFERROR(E45/D45,"") | J45: =IFERROR(H45/E45,"") | K45: =SUM(K24:K44) -> 0 | M45: =SUM(M24:M44) -> 0 | N45: =IFERROR(H45-Wk4!H45,"") -> 0 | O45: =IFERROR(D45-Wk4!D45,"") -> 0 | P45: =SUM(P24:P44) -> 0 | Q45: =SUM(Q24:Q44) -> 0 | R45: =IFERROR(INDEX('Last Year'!$C$6:$C$369,MATCH(B45-364,'Last Year'!$B$6:$B$369,0)),"") -> 0 | S45: =IFERROR(H45/R45-1,"")
A46: =TEXT(Setup!$C$5+30,"dddd") -> Wednesday | B46: =Setup!$C$5+30 -> 46057 | C46: 9.00 - 9.30 | P46: =IFERROR(H46/Setup!$C$6,"") -> 0 | Q46: =IFERROR(H46-P46,"") -> 0
A47: =TEXT(Setup!$C$5+30,"dddd") -> Wednesday | B47: =Setup!$C$5+30 -> 46057 | C47: 9.30 - 10.00 | P47: =IFERROR(H47/Setup!$C$6,"") -> 0 | Q47: =IFERROR(H47-P47,"") -> 0
A48: =TEXT(Setup!$C$5+30,"dddd") -> Wednesday | B48: =Setup!$C$5+30 -> 46057 | C48: 10.00 - 10.30 | P48: =IFERROR(H48/Setup!$C$6,"") -> 0 | Q48: =IFERROR(H48-P48,"") -> 0
A49: =TEXT(Setup!$C$5+30,"dddd") -> Wednesday | B49: =Setup!$C$5+30 -> 46057 | C49: 10.30 - 11.00 | P49: =IFERROR(H49/Setup!$C$6,"") -> 0 | Q49: =IFERROR(H49-P49,"") -> 0
A50: =TEXT(Setup!$C$5+30,"dddd") -> Wednesday | B50: =Setup!$C$5+30 -> 46057 | C50: 11.00 - 11.30 | P50: =IFERROR(H50/Setup!$C$6,"") -> 0 | Q50: =IFERROR(H50-P50,"") -> 0
A51: =TEXT(Setup!$C$5+30,"dddd") -> Wednesday | B51: =Setup!$C$5+30 -> 46057 | C51: 11.30 - 12.00 | P51: =IFERROR(H51/Setup!$C$6,"") -> 0 | Q51: =IFERROR(H51-P51,"") -> 0
A52: =TEXT(Setup!$C$5+30,"dddd") -> Wednesday | B52: =Setup!$C$5+30 -> 46057 | C52: 12.00 - 12.30 | P52: =IFERROR(H52/Setup!$C$6,"") -> 0 | Q52: =IFERROR(H52-P52,"") -> 0
A53: =TEXT(Setup!$C$5+30,"dddd") -> Wednesday | B53: =Setup!$C$5+30 -> 46057 | C53: 12.30 - 13.00 | P53: =IFERROR(H53/Setup!$C$6,"") -> 0 | Q53: =IFERROR(H53-P53,"") -> 0
A54: =TEXT(Setup!$C$5+30,"dddd") -> Wednesday | B54: =Setup!$C$5+30 -> 46057 | C54: 13.00 - 13.30 | P54: =IFERROR(H54/Setup!$C$6,"") -> 0 | Q54: =IFERROR(H54-P54,"") -> 0
A55: =TEXT(Setup!$C$5+30,"dddd") -> Wednesday | B55: =Setup!$C$5+30 -> 46057 | C55: 13.30 - 14.00 | P55: =IFERROR(H55/Setup!$C$6,"") -> 0 | Q55: =IFERROR(H55-P55,"") -> 0
A56: =TEXT(Setup!$C$5+30,"dddd") -> Wednesday | B56: =Setup!$C$5+30 -> 46057 | C56: 14.00 - 14.30 | P56: =IFERROR(H56/Setup!$C$6,"") -> 0 | Q56: =IFERROR(H56-P56,"") -> 0
...

Sheet Wk6
A1: Day | B1: Date | C1: Time | D1: Customers In | E1: Sales | F1: Vouchers Used | G1: Walk In/Out | H1: Sale Amount | I1: Conversion | J1: Avg Sale | K1: Tracked Category | L1: Notes | M1: Cash | N1: vs Last Wk € | O1: vs Last Wk Cust | P1: Est. Cost | Q1: Est. Profit | R1: Last Year Day | S1: vs Last Year
A2: =TEXT(Setup!$C$5+35,"dddd") -> Monday | B2: =Setup!$C$5+35 -> 46062 | C2: 9.00 - 9.30 | P2: =IFERROR(H2/Setup!$C$6,"") -> 0 | Q2: =IFERROR(H2-P2,"") -> 0
A3: =TEXT(Setup!$C$5+35,"dddd") -> Monday | B3: =Setup!$C$5+35 -> 46062 | C3: 9.30 - 10.00 | P3: =IFERROR(H3/Setup!$C$6,"") -> 0 | Q3: =IFERROR(H3-P3,"") -> 0
A4: =TEXT(Setup!$C$5+35,"dddd") -> Monday | B4: =Setup!$C$5+35 -> 46062 | C4: 10.00 - 10.30 | P4: =IFERROR(H4/Setup!$C$6,"") -> 0 | Q4: =IFERROR(H4-P4,"") -> 0
A5: =TEXT(Setup!$C$5+35,"dddd") -> Monday | B5: =Setup!$C$5+35 -> 46062 | C5: 10.30 - 11.00 | P5: =IFERROR(H5/Setup!$C$6,"") -> 0 | Q5: =IFERROR(H5-P5,"") -> 0
A6: =TEXT(Setup!$C$5+35,"dddd") -> Monday | B6: =Setup!$C$5+35 -> 46062 | C6: 11.00 - 11.30 | P6: =IFERROR(H6/Setup!$C$6,"") -> 0 | Q6: =IFERROR(H6-P6,"") -> 0
A7: =TEXT(Setup!$C$5+35,"dddd") -> Monday | B7: =Setup!$C$5+35 -> 46062 | C7: 11.30 - 12.00 | P7: =IFERROR(H7/Setup!$C$6,"") -> 0 | Q7: =IFERROR(H7-P7,"") -> 0
A8: =TEXT(Setup!$C$5+35,"dddd") -> Monday | B8: =Setup!$C$5+35 -> 46062 | C8: 12.00 - 12.30 | P8: =IFERROR(H8/Setup!$C$6,"") -> 0 | Q8: =IFERROR(H8-P8,"") -> 0
A9: =TEXT(Setup!$C$5+35,"dddd") -> Monday | B9: =Setup!$C$5+35 -> 46062 | C9: 12.30 - 13.00 | P9: =IFERROR(H9/Setup!$C$6,"") -> 0 | Q9: =IFERROR(H9-P9,"") -> 0
A10: =TEXT(Setup!$C$5+35,"dddd") -> Monday | B10: =Setup!$C$5+35 -> 46062 | C10: 13.00 - 13.30 | P10: =IFERROR(H10/Setup!$C$6,"") -> 0 | Q10: =IFERROR(H10-P10,"") -> 0
A11: =TEXT(Setup!$C$5+35,"dddd") -> Monday | B11: =Setup!$C$5+35 -> 46062 | C11: 13.30 - 14.00 | P11: =IFERROR(H11/Setup!$C$6,"") -> 0 | Q11: =IFERROR(H11-P11,"") -> 0
A12: =TEXT(Setup!$C$5+35,"dddd") -> Monday | B12: =Setup!$C$5+35 -> 46062 | C12: 14.00 - 14.30 | P12: =IFERROR(H12/Setup!$C$6,"") -> 0 | Q12: =IFERROR(H12-P12,"") -> 0
A13: =TEXT(Setup!$C$5+35,"dddd") -> Monday | B13: =Setup!$C$5+35 -> 46062 | C13: 14.30 - 15.00 | P13: =IFERROR(H13/Setup!$C$6,"") -> 0 | Q13: =IFERROR(H13-P13,"") -> 0
... A22: =TEXT(Setup!$C$5+35,"dddd") -> Monday | B22: =Setup!$C$5+35 -> 46062 | C22: ONLINE | P22: =IFERROR(H22/Setup!$C$6,"") -> 0 | Q22: =IFERROR(H22-P22,"") -> 0
A23: =TEXT(Setup!$C$5+35,"dddd") -> Monday | B23: =Setup!$C$5+35 -> 46062 | C23: TOTAL | D23: =SUM(D2:D22) -> 0 | E23: =SUM(E2:E22) -> 0 | F23: =SUM(F2:F22) -> 0 | G23: =SUM(G2:G22) -> 0 | H23: =SUM(H2:H22) -> 0 | I23: =IFERROR(E23/D23,"") | J23: =IFERROR(H23/E23,"") | K23: =SUM(K2:K22) -> 0 | M23: =SUM(M2:M22) -> 0 | N23: =IFERROR(H23-Wk5!H23,"") -> 0 | O23: =IFERROR(D23-Wk5!D23,"") -> 0 | P23: =SUM(P2:P22) -> 0 | Q23: =SUM(Q2:Q22) -> 0 | R23: =IFERROR(INDEX('Last Year'!$C$6:$C$369,MATCH(B23-364,'Last Year'!$B$6:$B$369,0)),"") -> 0 | S23: =IFERROR(H23/R23-1,"")
A24: =TEXT(Setup!$C$5+36,"dddd") -> Tuesday | B24: =Setup!$C$5+36 -> 46063 | C24: 9.00 - 9.30 | P24: =IFERROR(H24/Setup!$C$6,"") -> 0 | Q24: =IFERROR(H24-P24,"") -> 0
A25: =TEXT(Setup!$C$5+36,"dddd") -> Tuesday | B25: =Setup!$C$5+36 -> 46063 | C25: 9.30 - 10.00 | P25: =IFERROR(H25/Setup!$C$6,"") -> 0 | Q25: =IFERROR(H25-P25,"") -> 0
A26: =TEXT(Setup!$C$5+36,"dddd") -> Tuesday | B26: =Setup!$C$5+36 -> 46063 | C26: 10.00 - 10.30 | P26: =IFERROR(H26/Setup!$C$6,"") -> 0 | Q26: =IFERROR(H26-P26,"") -> 0
A27: =TEXT(Setup!$C$5+36,"dddd") -> Tuesday | B27: =Setup!$C$5+36 -> 46063 | C27: 10.30 - 11.00 | P27: =IFERROR(H27/Setup!$C$6,"") -> 0 | Q27: =IFERROR(H27-P27,"") -> 0
A28: =TEXT(Setup!$C$5+36,"dddd") -> Tuesday | B28: =Setup!$C$5+36 -> 46063 | C28: 11.00 - 11.30 | P28: =IFERROR(H28/Setup!$C$6,"") -> 0 | Q28: =IFERROR(H28-P28,"") -> 0
A29: =TEXT(Setup!$C$5+36,"dddd") -> Tuesday | B29: =Setup!$C$5+36 -> 46063 | C29: 11.30 - 12.00 | P29: =IFERROR(H29/Setup!$C$6,"") -> 0 | Q29: =IFERROR(H29-P29,"") -> 0
A30: =TEXT(Setup!$C$5+36,"dddd") -> Tuesday | B30: =Setup!$C$5+36 -> 46063 | C30: 12.00 - 12.30 | P30: =IFERROR(H30/Setup!$C$6,"") -> 0 | Q30: =IFERROR(H30-P30,"") -> 0
A31: =TEXT(Setup!$C$5+36,"dddd") -> Tuesday | B31: =Setup!$C$5+36 -> 46063 | C31: 12.30 - 13.00 | P31: =IFERROR(H31/Setup!$C$6,"") -> 0 | Q31: =IFERROR(H31-P31,"") -> 0
A32: =TEXT(Setup!$C$5+36,"dddd") -> Tuesday | B32: =Setup!$C$5+36 -> 46063 | C32: 13.00 - 13.30 | P32: =IFERROR(H32/Setup!$C$6,"") -> 0 | Q32: =IFERROR(H32-P32,"") -> 0
A33: =TEXT(Setup!$C$5+36,"dddd") -> Tuesday | B33: =Setup!$C$5+36 -> 46063 | C33: 13.30 - 14.00 | P33: =IFERROR(H33/Setup!$C$6,"") -> 0 | Q33: =IFERROR(H33-P33,"") -> 0
A34: =TEXT(Setup!$C$5+36,"dddd") -> Tuesday | B34: =Setup!$C$5+36 -> 46063 | C34: 14.00 - 14.30 | P34: =IFERROR(H34/Setup!$C$6,"") -> 0 | Q34: =IFERROR(H34-P34,"") -> 0
A35: =TEXT(Setup!$C$5+36,"dddd") -> Tuesday | B35: =Setup!$C$5+36 -> 46063 | C35: 14.30 - 15.00 | P35: =IFERROR(H35/Setup!$C$6,"") -> 0 | Q35: =IFERROR(H35-P35,"") -> 0
... A44: =TEXT(Setup!$C$5+36,"dddd") -> Tuesday | B44: =Setup!$C$5+36 -> 46063 | C44: ONLINE | P44: =IFERROR(H44/Setup!$C$6,"") -> 0 | Q44: =IFERROR(H44-P44,"") -> 0
A45: =TEXT(Setup!$C$5+36,"dddd") -> Tuesday | B45: =Setup!$C$5+36 -> 46063 | C45: TOTAL | D45: =SUM(D24:D44) -> 0 | E45: =SUM(E24:E44) -> 0 | F45: =SUM(F24:F44) -> 0 | G45: =SUM(G24:G44) -> 0 | H45: =SUM(H24:H44) -> 0 | I45: =IFERROR(E45/D45,"") | J45: =IFERROR(H45/E45,"") | K45: =SUM(K24:K44) -> 0 | M45: =SUM(M24:M44) -> 0 | N45: =IFERROR(H45-Wk5!H45,"") -> 0 | O45: =IFERROR(D45-Wk5!D45,"") -> 0 | P45: =SUM(P24:P44) -> 0 | Q45: =SUM(Q24:Q44) -> 0 | R45: =IFERROR(INDEX('Last Year'!$C$6:$C$369,MATCH(B45-364,'Last Year'!$B$6:$B$369,0)),"") -> 0 | S45: =IFERROR(H45/R45-1,"")
A46: =TEXT(Setup!$C$5+37,"dddd") -> Wednesday | B46: =Setup!$C$5+37 -> 46064 | C46: 9.00 - 9.30 | P46: =IFERROR(H46/Setup!$C$6,"") -> 0 | Q46: =IFERROR(H46-P46,"") -> 0
A47: =TEXT(Setup!$C$5+37,"dddd") -> Wednesday | B47: =Setup!$C$5+37 -> 46064 | C47: 9.30 - 10.00 | P47: =IFERROR(H47/Setup!$C$6,"") -> 0 | Q47: =IFERROR(H47-P47,"") -> 0
A48: =TEXT(Setup!$C$5+37,"dddd") -> Wednesday | B48: =Setup!$C$5+37 -> 46064 | C48: 10.00 - 10.30 | P48: =IFERROR(H48/Setup!$C$6,"") -> 0 | Q48: =IFERROR(H48-P48,"") -> 0
A49: =TEXT(Setup!$C$5+37,"dddd") -> Wednesday | B49: =Setup!$C$5+37 -> 46064 | C49: 10.30 - 11.00 | P49: =IFERROR(H49/Setup!$C$6,"") -> 0 | Q49: =IFERROR(H49-P49,"") -> 0
A50: =TEXT(Setup!$C$5+37,"dddd") -> Wednesday | B50: =Setup!$C$5+37 -> 46064 | C50: 11.00 - 11.30 | P50: =IFERROR(H50/Setup!$C$6,"") -> 0 | Q50: =IFERROR(H50-P50,"") -> 0
A51: =TEXT(Setup!$C$5+37,"dddd") -> Wednesday | B51: =Setup!$C$5+37 -> 46064 | C51: 11.30 - 12.00 | P51: =IFERROR(H51/Setup!$C$6,"") -> 0 | Q51: =IFERROR(H51-P51,"") -> 0
A52: =TEXT(Setup!$C$5+37,"dddd") -> Wednesday | B52: =Setup!$C$5+37 -> 46064 | C52: 12.00 - 12.30 | P52: =IFERROR(H52/Setup!$C$6,"") -> 0 | Q52: =IFERROR(H52-P52,"") -> 0
A53: =TEXT(Setup!$C$5+37,"dddd") -> Wednesday | B53: =Setup!$C$5+37 -> 46064 | C53: 12.30 - 13.00 | P53: =IFERROR(H53/Setup!$C$6,"") -> 0 | Q53: =IFERROR(H53-P53,"") -> 0
A54: =TEXT(Setup!$C$5+37,"dddd") -> Wednesday | B54: =Setup!$C$5+37 -> 46064 | C54: 13.00 - 13.30 | P54: =IFERROR(H54/Setup!$C$6,"") -> 0 | Q54: =IFERROR(H54-P54,"") -> 0
A55: =TEXT(Setup!$C$5+37,"dddd") -> Wednesday | B55: =Setup!$C$5+37 -> 46064 | C55: 13.30 - 14.00 | P55: =IFERROR(H55/Setup!$C$6,"") -> 0 | Q55: =IFERROR(H55-P55,"") -> 0
A56: =TEXT(Setup!$C$5+37,"dddd") -> Wednesday | B56: =Setup!$C$5+37 -> 46064 | C56: 14.00 - 14.30 | P56: =IFERROR(H56/Setup!$C$6,"") -> 0 | Q56: =IFERROR(H56-P56,"") -> 0
...

Sheet Wk7
A1: Day | B1: Date | C1: Time | D1: Customers In | E1: Sales | F1: Vouchers Used | G1: Walk In/Out | H1: Sale Amount | I1: Conversion | J1: Avg Sale | K1: Tracked Category | L1: Notes | M1: Cash | N1: vs Last Wk € | O1: vs Last Wk Cust | P1: Est. Cost | Q1: Est. Profit | R1: Last Year Day | S1: vs Last Year
A2: =TEXT(Setup!$C$5+42,"dddd") -> Monday | B2: =Setup!$C$5+42 -> 46069 | C2: 9.00 - 9.30 | P2: =IFERROR(H2/Setup!$C$6,"") -> 0 | Q2: =IFERROR(H2-P2,"") -> 0
A3: =TEXT(Setup!$C$5+42,"dddd") -> Monday | B3: =Setup!$C$5+42 -> 46069 | C3: 9.30 - 10.00 | P3: =IFERROR(H3/Setup!$C$6,"") -> 0 | Q3: =IFERROR(H3-P3,"") -> 0
A4: =TEXT(Setup!$C$5+42,"dddd") -> Monday | B4: =Setup!$C$5+42 -> 46069 | C4: 10.00 - 10.30 | P4: =IFERROR(H4/Setup!$C$6,"") -> 0 | Q4: =IFERROR(H4-P4,"") -> 0
A5: =TEXT(Setup!$C$5+42,"dddd") -> Monday | B5: =Setup!$C$5+42 -> 46069 | C5: 10.30 - 11.00 | P5: =IFERROR(H5/Setup!$C$6,"") -> 0 | Q5: =IFERROR(H5-P5,"") -> 0
A6: =TEXT(Setup!$C$5+42,"dddd") -> Monday | B6: =Setup!$C$5+42 -> 46069 | C6: 11.00 - 11.30 | P6: =IFERROR(H6/Setup!$C$6,"") -> 0 | Q6: =IFERROR(H6-P6,"") -> 0
A7: =TEXT(Setup!$C$5+42,"dddd") -> Monday | B7: =Setup!$C$5+42 -> 46069 | C7: 11.30 - 12.00 | P7: =IFERROR(H7/Setup!$C$6,"") -> 0 | Q7: =IFERROR(H7-P7,"") -> 0
A8: =TEXT(Setup!$C$5+42,"dddd") -> Monday | B8: =Setup!$C$5+42 -> 46069 | C8: 12.00 - 12.30 | P8: =IFERROR(H8/Setup!$C$6,"") -> 0 | Q8: =IFERROR(H8-P8,"") -> 0
A9: =TEXT(Setup!$C$5+42,"dddd") -> Monday | B9: =Setup!$C$5+42 -> 46069 | C9: 12.30 - 13.00 | P9: =IFERROR(H9/Setup!$C$6,"") -> 0 | Q9: =IFERROR(H9-P9,"") -> 0
A10: =TEXT(Setup!$C$5+42,"dddd") -> Monday | B10: =Setup!$C$5+42 -> 46069 | C10: 13.00 - 13.30 | P10: =IFERROR(H10/Setup!$C$6,"") -> 0 | Q10: =IFERROR(H10-P10,"") -> 0
A11: =TEXT(Setup!$C$5+42,"dddd") -> Monday | B11: =Setup!$C$5+42 -> 46069 | C11: 13.30 - 14.00 | P11: =IFERROR(H11/Setup!$C$6,"") -> 0 | Q11: =IFERROR(H11-P11,"") -> 0
A12: =TEXT(Setup!$C$5+42,"dddd") -> Monday | B12: =Setup!$C$5+42 -> 46069 | C12: 14.00 - 14.30 | P12: =IFERROR(H12/Setup!$C$6,"") -> 0 | Q12: =IFERROR(H12-P12,"") -> 0
A13: =TEXT(Setup!$C$5+42,"dddd") -> Monday | B13: =Setup!$C$5+42 -> 46069 | C13: 14.30 - 15.00 | P13: =IFERROR(H13/Setup!$C$6,"") -> 0 | Q13: =IFERROR(H13-P13,"") -> 0
... A22: =TEXT(Setup!$C$5+42,"dddd") -> Monday | B22: =Setup!$C$5+42 -> 46069 | C22: ONLINE | P22: =IFERROR(H22/Setup!$C$6,"") -> 0 | Q22: =IFERROR(H22-P22,"") -> 0
A23: =TEXT(Setup!$C$5+42,"dddd") -> Monday | B23: =Setup!$C$5+42 -> 46069 | C23: TOTAL | D23: =SUM(D2:D22) -> 0 | E23: =SUM(E2:E22) -> 0 | F23: =SUM(F2:F22) -> 0 | G23: =SUM(G2:G22) -> 0 | H23: =SUM(H2:H22) -> 0 | I23: =IFERROR(E23/D23,"") | J23: =IFERROR(H23/E23,"") | K23: =SUM(K2:K22) -> 0 | M23: =SUM(M2:M22) -> 0 | N23: =IFERROR(H23-Wk6!H23,"") -> 0 | O23: =IFERROR(D23-Wk6!D23,"") -> 0 | P23: =SUM(P2:P22) -> 0 | Q23: =SUM(Q2:Q22) -> 0 | R23: =IFERROR(INDEX('Last Year'!$C$6:$C$369,MATCH(B23-364,'Last Year'!$B$6:$B$369,0)),"") -> 0 | S23: =IFERROR(H23/R23-1,"")
A24: =TEXT(Setup!$C$5+43,"dddd") -> Tuesday | B24: =Setup!$C$5+43 -> 46070 | C24: 9.00 - 9.30 | P24: =IFERROR(H24/Setup!$C$6,"") -> 0 | Q24: =IFERROR(H24-P24,"") -> 0
A25: =TEXT(Setup!$C$5+43,"dddd") -> Tuesday | B25: =Setup!$C$5+43 -> 46070 | C25: 9.30 - 10.00 | P25: =IFERROR(H25/Setup!$C$6,"") -> 0 | Q25: =IFERROR(H25-P25,"") -> 0
A26: =TEXT(Setup!$C$5+43,"dddd") -> Tuesday | B26: =Setup!$C$5+43 -> 46070 | C26: 10.00 - 10.30 | P26: =IFERROR(H26/Setup!$C$6,"") -> 0 | Q26: =IFERROR(H26-P26,"") -> 0
A27: =TEXT(Setup!$C$5+43,"dddd") -> Tuesday | B27: =Setup!$C$5+43 -> 46070 | C27: 10.30 - 11.00 | P27: =IFERROR(H27/Setup!$C$6,"") -> 0 | Q27: =IFERROR(H27-P27,"") -> 0
A28: =TEXT(Setup!$C$5+43,"dddd") -> Tuesday | B28: =Setup!$C$5+43 -> 46070 | C28: 11.00 - 11.30 | P28: =IFERROR(H28/Setup!$C$6,"") -> 0 | Q28: =IFERROR(H28-P28,"") -> 0
A29: =TEXT(Setup!$C$5+43,"dddd") -> Tuesday | B29: =Setup!$C$5+43 -> 46070 | C29: 11.30 - 12.00 | P29: =IFERROR(H29/Setup!$C$6,"") -> 0 | Q29: =IFERROR(H29-P29,"") -> 0
A30: =TEXT(Setup!$C$5+43,"dddd") -> Tuesday | B30: =Setup!$C$5+43 -> 46070 | C30: 12.00 - 12.30 | P30: =IFERROR(H30/Setup!$C$6,"") -> 0 | Q30: =IFERROR(H30-P30,"") -> 0
A31: =TEXT(Setup!$C$5+43,"dddd") -> Tuesday | B31: =Setup!$C$5+43 -> 46070 | C31: 12.30 - 13.00 | P31: =IFERROR(H31/Setup!$C$6,"") -> 0 | Q31: =IFERROR(H31-P31,"") -> 0
A32: =TEXT(Setup!$C$5+43,"dddd") -> Tuesday | B32: =Setup!$C$5+43 -> 46070 | C32: 13.00 - 13.30 | P32: =IFERROR(H32/Setup!$C$6,"") -> 0 | Q32: =IFERROR(H32-P32,"") -> 0
A33: =TEXT(Setup!$C$5+43,"dddd") -> Tuesday | B33: =Setup!$C$5+43 -> 46070 | C33: 13.30 - 14.00 | P33: =IFERROR(H33/Setup!$C$6,"") -> 0 | Q33: =IFERROR(H33-P33,"") -> 0
A34: =TEXT(Setup!$C$5+43,"dddd") -> Tuesday | B34: =Setup!$C$5+43 -> 46070 | C34: 14.00 - 14.30 | P34: =IFERROR(H34/Setup!$C$6,"") -> 0 | Q34: =IFERROR(H34-P34,"") -> 0
A35: =TEXT(Setup!$C$5+43,"dddd") -> Tuesday | B35: =Setup!$C$5+43 -> 46070 | C35: 14.30 - 15.00 | P35: =IFERROR(H35/Setup!$C$6,"") -> 0 | Q35: =IFERROR(H35-P35,"") -> 0
... A44: =TEXT(Setup!$C$5+43,"dddd") -> Tuesday | B44: =Setup!$C$5+43 -> 46070 | C44: ONLINE | P44: =IFERROR(H44/Setup!$C$6,"") -> 0 | Q44: =IFERROR(H44-P44,"") -> 0
A45: =TEXT(Setup!$C$5+43,"dddd") -> Tuesday | B45: =Setup!$C$5+43 -> 46070 | C45: TOTAL | D45: =SUM(D24:D44) -> 0 | E45: =SUM(E24:E44) -> 0 | F45: =SUM(F24:F44) -> 0 | G45: =SUM(G24:G44) -> 0 | H45: =SUM(H24:H44) -> 0 | I45: =IFERROR(E45/D45,"") | J45: =IFERROR(H45/E45,"") | K45: =SUM(K24:K44) -> 0 | M45: =SUM(M24:M44) -> 0 | N45: =IFERROR(H45-Wk6!H45,"") -> 0 | O45: =IFERROR(D45-Wk6!D45,"") -> 0 | P45: =SUM(P24:P44) -> 0 | Q45: =SUM(Q24:Q44) -> 0 | R45: =IFERROR(INDEX('Last Year'!$C$6:$C$369,MATCH(B45-364,'Last Year'!$B$6:$B$369,0)),"") -> 0 | S45: =IFERROR(H45/R45-1,"")
A46: =TEXT(Setup!$C$5+44,"dddd") -> Wednesday | B46: =Setup!$C$5+44 -> 46071 | C46: 9.00 - 9.30 | P46: =IFERROR(H46/Setup!$C$6,"") -> 0 | Q46: =IFERROR(H46-P46,"") -> 0
A47: =TEXT(Setup!$C$5+44,"dddd") -> Wednesday | B47: =Setup!$C$5+44 -> 46071 | C47: 9.30 - 10.00 | P47: =IFERROR(H47/Setup!$C$6,"") -> 0 | Q47: =IFERROR(H47-P47,"") -> 0
A48: =TEXT(Setup!$C$5+44,"dddd") -> Wednesday | B48: =Setup!$C$5+44 -> 46071 | C48: 10.00 - 10.30 | P48: =IFERROR(H48/Setup!$C$6,"") -> 0 | Q48: =IFERROR(H48-P48,"") -> 0
A49: =TEXT(Setup!$C$5+44,"dddd") -> Wednesday | B49: =Setup!$C$5+44 -> 46071 | C49: 10.30 - 11.00 | P49: =IFERROR(H49/Setup!$C$6,"") -> 0 | Q49: =IFERROR(H49-P49,"") -> 0
A50: =TEXT(Setup!$C$5+44,"dddd") -> Wednesday | B50: =Setup!$C$5+44 -> 46071 | C50: 11.00 - 11.30 | P50: =IFERROR(H50/Setup!$C$6,"") -> 0 | Q50: =IFERROR(H50-P50,"") -> 0
A51: =TEXT(Setup!$C$5+44,"dddd") -> Wednesday | B51: =Setup!$C$5+44 -> 46071 | C51: 11.30 - 12.00 | P51: =IFERROR(H51/Setup!$C$6,"") -> 0 | Q51: =IFERROR(H51-P51,"") -> 0
A52: =TEXT(Setup!$C$5+44,"dddd") -> Wednesday | B52: =Setup!$C$5+44 -> 46071 | C52: 12.00 - 12.30 | P52: =IFERROR(H52/Setup!$C$6,"") -> 0 | Q52: =IFERROR(H52-P52,"") -> 0
A53: =TEXT(Setup!$C$5+44,"dddd") -> Wednesday | B53: =Setup!$C$5+44 -> 46071 | C53: 12.30 - 13.00 | P53: =IFERROR(H53/Setup!$C$6,"") -> 0 | Q53: =IFERROR(H53-P53,"") -> 0
A54: =TEXT(Setup!$C$5+44,"dddd") -> Wednesday | B54: =Setup!$C$5+44 -> 46071 | C54: 13.00 - 13.30 | P54: =IFERROR(H54/Setup!$C$6,"") -> 0 | Q54: =IFERROR(H54-P54,"") -> 0
A55: =TEXT(Setup!$C$5+44,"dddd") -> Wednesday | B55: =Setup!$C$5+44 -> 46071 | C55: 13.30 - 14.00 | P55: =IFERROR(H55/Setup!$C$6,"") -> 0 | Q55: =IFERROR(H55-P55,"") -> 0
A56: =TEXT(Setup!$C$5+44,"dddd") -> Wednesday | B56: =Setup!$C$5+44 -> 46071 | C56: 14.00 - 14.30 | P56: =IFERROR(H56/Setup!$C$6,"") -> 0 | Q56: =IFERROR(H56-P56,"") -> 0
...

Sheet Wk8
A1: Day | B1: Date | C1: Time | D1: Customers In | E1: Sales | F1: Vouchers Used | G1: Walk In/Out | H1: Sale Amount | I1: Conversion | J1: Avg Sale | K1: Tracked Category | L1: Notes | M1: Cash | N1: vs Last Wk € | O1: vs Last Wk Cust | P1: Est. Cost | Q1: Est. Profit | R1: Last Year Day | S1: vs Last Year
A2: =TEXT(Setup!$C$5+49,"dddd") -> Monday | B2: =Setup!$C$5+49 -> 46076 | C2: 9.00 - 9.30 | P2: =IFERROR(H2/Setup!$C$6,"") -> 0 | Q2: =IFERROR(H2-P2,"") -> 0
A3: =TEXT(Setup!$C$5+49,"dddd") -> Monday | B3: =Setup!$C$5+49 -> 46076 | C3: 9.30 - 10.00 | P3: =IFERROR(H3/Setup!$C$6,"") -> 0 | Q3: =IFERROR(H3-P3,"") -> 0
A4: =TEXT(Setup!$C$5+49,"dddd") -> Monday | B4: =Setup!$C$5+49 -> 46076 | C4: 10.00 - 10.30 | P4: =IFERROR(H4/Setup!$C$6,"") -> 0 | Q4: =IFERROR(H4-P4,"") -> 0
A5: =TEXT(Setup!$C$5+49,"dddd") -> Monday | B5: =Setup!$C$5+49 -> 46076 | C5: 10.30 - 11.00 | P5: =IFERROR(H5/Setup!$C$6,"") -> 0 | Q5: =IFERROR(H5-P5,"") -> 0
A6: =TEXT(Setup!$C$5+49,"dddd") -> Monday | B6: =Setup!$C$5+49 -> 46076 | C6: 11.00 - 11.30 | P6: =IFERROR(H6/Setup!$C$6,"") -> 0 | Q6: =IFERROR(H6-P6,"") -> 0
A7: =TEXT(Setup!$C$5+49,"dddd") -> Monday | B7: =Setup!$C$5+49 -> 46076 | C7: 11.30 - 12.00 | P7: =IFERROR(H7/Setup!$C$6,"") -> 0 | Q7: =IFERROR(H7-P7,"") -> 0
A8: =TEXT(Setup!$C$5+49,"dddd") -> Monday | B8: =Setup!$C$5+49 -> 46076 | C8: 12.00 - 12.30 | P8: =IFERROR(H8/Setup!$C$6,"") -> 0 | Q8: =IFERROR(H8-P8,"") -> 0
A9: =TEXT(Setup!$C$5+49,"dddd") -> Monday | B9: =Setup!$C$5+49 -> 46076 | C9: 12.30 - 13.00 | P9: =IFERROR(H9/Setup!$C$6,"") -> 0 | Q9: =IFERROR(H9-P9,"") -> 0
A10: =TEXT(Setup!$C$5+49,"dddd") -> Monday | B10: =Setup!$C$5+49 -> 46076 | C10: 13.00 - 13.30 | P10: =IFERROR(H10/Setup!$C$6,"") -> 0 | Q10: =IFERROR(H10-P10,"") -> 0
A11: =TEXT(Setup!$C$5+49,"dddd") -> Monday | B11: =Setup!$C$5+49 -> 46076 | C11: 13.30 - 14.00 | P11: =IFERROR(H11/Setup!$C$6,"") -> 0 | Q11: =IFERROR(H11-P11,"") -> 0
A12: =TEXT(Setup!$C$5+49,"dddd") -> Monday | B12: =Setup!$C$5+49 -> 46076 | C12: 14.00 - 14.30 | P12: =IFERROR(H12/Setup!$C$6,"") -> 0 | Q12: =IFERROR(H12-P12,"") -> 0
A13: =TEXT(Setup!$C$5+49,"dddd") -> Monday | B13: =Setup!$C$5+49 -> 46076 | C13: 14.30 - 15.00 | P13: =IFERROR(H13/Setup!$C$6,"") -> 0 | Q13: =IFERROR(H13-P13,"") -> 0
... A22: =TEXT(Setup!$C$5+49,"dddd") -> Monday | B22: =Setup!$C$5+49 -> 46076 | C22: ONLINE | P22: =IFERROR(H22/Setup!$C$6,"") -> 0 | Q22: =IFERROR(H22-P22,"") -> 0
A23: =TEXT(Setup!$C$5+49,"dddd") -> Monday | B23: =Setup!$C$5+49 -> 46076 | C23: TOTAL | D23: =SUM(D2:D22) -> 0 | E23: =SUM(E2:E22) -> 0 | F23: =SUM(F2:F22) -> 0 | G23: =SUM(G2:G22) -> 0 | H23: =SUM(H2:H22) -> 0 | I23: =IFERROR(E23/D23,"") | J23: =IFERROR(H23/E23,"") | K23: =SUM(K2:K22) -> 0 | M23: =SUM(M2:M22) -> 0 | N23: =IFERROR(H23-Wk7!H23,"") -> 0 | O23: =IFERROR(D23-Wk7!D23,"") -> 0 | P23: =SUM(P2:P22) -> 0 | Q23: =SUM(Q2:Q22) -> 0 | R23: =IFERROR(INDEX('Last Year'!$C$6:$C$369,MATCH(B23-364,'Last Year'!$B$6:$B$369,0)),"") -> 0 | S23: =IFERROR(H23/R23-1,"")
A24: =TEXT(Setup!$C$5+50,"dddd") -> Tuesday | B24: =Setup!$C$5+50 -> 46077 | C24: 9.00 - 9.30 | P24: =IFERROR(H24/Setup!$C$6,"") -> 0 | Q24: =IFERROR(H24-P24,"") -> 0
A25: =TEXT(Setup!$C$5+50,"dddd") -> Tuesday | B25: =Setup!$C$5+50 -> 46077 | C25: 9.30 - 10.00 | P25: =IFERROR(H25/Setup!$C$6,"") -> 0 | Q25: =IFERROR(H25-P25,"") -> 0
A26: =TEXT(Setup!$C$5+50,"dddd") -> Tuesday | B26: =Setup!$C$5+50 -> 46077 | C26: 10.00 - 10.30 | P26: =IFERROR(H26/Setup!$C$6,"") -> 0 | Q26: =IFERROR(H26-P26,"") -> 0
A27: =TEXT(Setup!$C$5+50,"dddd") -> Tuesday | B27: =Setup!$C$5+50 -> 46077 | C27: 10.30 - 11.00 | P27: =IFERROR(H27/Setup!$C$6,"") -> 0 | Q27: =IFERROR(H27-P27,"") -> 0
A28: =TEXT(Setup!$C$5+50,"dddd") -> Tuesday | B28: =Setup!$C$5+50 -> 46077 | C28: 11.00 - 11.30 | P28: =IFERROR(H28/Setup!$C$6,"") -> 0 | Q28: =IFERROR(H28-P28,"") -> 0
A29: =TEXT(Setup!$C$5+50,"dddd") -> Tuesday | B29: =Setup!$C$5+50 -> 46077 | C29: 11.30 - 12.00 | P29: =IFERROR(H29/Setup!$C$6,"") -> 0 | Q29: =IFERROR(H29-P29,"") -> 0
A30: =TEXT(Setup!$C$5+50,"dddd") -> Tuesday | B30: =Setup!$C$5+50 -> 46077 | C30: 12.00 - 12.30 | P30: =IFERROR(H30/Setup!$C$6,"") -> 0 | Q30: =IFERROR(H30-P30,"") -> 0
